Workbook

Sheet 24年对比25年老店营业额
B1: 市场2024年-2025年营业额统计表
B2: 年份 | C2: 1月 | D2: 2月 | E2: 3月 | F2: 4月 | G2: 5月 | H2: 6月 | I2: 7月 | J2: 8月 | K2: 9月 | L2: 10月 | M2: 11月 | N2: 12月 | O2: 合计
B4: 2024年 | C4: 932103.3 | D4: 652349 | E4: 945464.1 | F4: 915125.2 | G4: 1027966.8 | H4: 1007880.1 | I4: 1064341.1 | J4: 1283617.3 | K4: 1121387 | L4: 1150757.4 | M4: 1229094.7 | N4: 1232186.1 | O4: =SUM(C4:N4) -> 12562272
B5: 2025年 | C5: 1085927.7 | D5: 1164055.8 | E5: 1368149.8 | F5: 1425158.8 | G5: 1452104 | H5: 1392730.5 | I5: 1629481.2 | J5: 1619943.3 | K5: 1498782.2 | L5: 1571954.8 | M5: 1536909.3 | N5: 1757816.4 | O5: =SUM(C5:N5) -> 17503014 | P5: =O5*(1+6%) -> 18553195
B6: 25年vs24年 | C6: =(C5-C4)/C4 -> 0.16502931 | D6: =(D5-D4)/D4 -> 0.78440646 | E6: =(E5-E4)/E4 -> 0.44706687 | F6: =(F5-F4)/F4 -> 0.55733748 | G6: =(G5-G4)/G4 -> 0.4125982 | H6: =(H5-H4)/H4 -> 0.38184141 | I6: =(I5-I4)/I4 -> 0.53097654 | J6: =(J5-J4)/J4 -> 0.2620142 | ... O6: =(O5-O4)/O4 -> 0.3933
B7: 25年vs24年 | C7: =C5-C4 -> 153824.36 | D7: =D5-D4 -> 511706.77 | E7: =E5-E4 -> 422685.68 | F7: =F5-F4 -> 510033.57 | G7: =G5-G4 -> 424137.23 | H7: =H5-H4 -> 384850.37 | I7: =I5-I4 -> 565140.15 | J7: =J5-J4 -> 336325.96 | ... O7: =O5-O4 -> 4940741.6
B8: 25年对比24年新增门店 ： 2-12月 铁机路的营业额； 1-10月蔡甸中百店营业额； 3-12月东辉店营业额；
B10: 市场2024年-2025年TC统计
B11: 年份 | C11: 1月 | D11: 2月 | E11: 3月 | F11: 4月 | G11: 5月 | H11: 6月 | I11: 7月 | J11: 8月 | K11: 9月 | L11: 10月 | M11: 11月 | N11: 12月 | O11: 合计
B13: 2024年 | C13: 92176 | D13: 60296 | E13: 93724 | F13: 91206 | G13: 92545 | H13: 84451 | I13: 96771 | J13: 116220 | K13: 105593 | L13: 106649 | M13: 117268 | N13: 118073 | O13: =SUM(C13:N13) -> 1174972
B14: 2025年 | C14: 104165 | D14: 114819 | E14: 134817 | F14: 140245 | G14: 142720 | H14: 134878 | I14: 156641 | J14: 153857 | K14: 146132 | L14: 146849 | M14: 144105 | N14: 162112 | O14: =SUM(C14:N14) -> 1681340
B15: 25年vs24年 | C15: =(C14-C13)/C13 -> 0.13006639 | D15: =(D14-D13)/D13 -> 0.90425567 | E15: =(E14-E13)/E13 -> 0.43844693 | F15: =(F14-F13)/F13 -> 0.53767296 | G15: =(G14-G13)/G13 -> 0.54216867 | H15: =(H14-H13)/H13 -> 0.59711549 | I15: =(I14-I13)/I13 -> 0.61867708 | J15: =(J14-J13)/J13 -> 0.32384271 | ... O15: =(O14-O13)/O13 -> 0.43096176
B16: 25年vs24年 | C16: =C14-C13 -> 11989 | D16: =D14-D13 -> 54523 | E16: =E14-E13 -> 41093 | F16: =F14-F13 -> 49039 | G16: =G14-G13 -> 50175 | H16: =H14-H13 -> 50427 | I16: =I14-I13 -> 59870 | J16: =J14-J13 -> 37637 | ... O16: =O14-O13 -> 506368
B18: 市场2024年-2025年AC统计
B19: 年份 | C19: 1月 | D19: 2月 | E19: 3月 | F19: 4月 | G19: 5月 | H19: 6月 | I19: 7月 | J19: 8月 | K19: 9月 | L19: 10月 | M19: 11月 | N19: 12月 | O19: 年平均
B21: 2024年 | C21: =C4/C13 -> 10.112213 | D21: =D4/D13 -> 10.819109 | E21: =E4/E13 -> 10.087748 | F21: =F4/F13 -> 10.033607 | G21: =G4/G13 -> 11.10775 | H21: =H4/H13 -> 11.934496 | I21: =I4/I13 -> 10.998554 | J21: =J4/J13 -> 11.044719 | ... N21: =N4/N13 -> 10.435799 | O21: =AVERAGE(C21:N21) -> 10.705426
B22: 2025年 | C22: =C5/C14 -> 10.425072 | D22: =D5/D14 -> 10.138181 | E22: =E5/E14 -> 10.148199 | F22: =F5/F14 -> 10.161922 | G22: =G5/G14 -> 10.174495 | H22: =H5/H14 -> 10.325854 | I22: =I5/I14 -> 10.402648 | J22: =J5/J14 -> 10.528889 | ... N22: =N5/N14 -> 10.843222 | O22: =AVERAGE(C22:N22) -> 10.397884
B23: 25年vs24年 | C23: =(C22-C21)/C21 -> 0.030938811 | D23: =(D22-D21)/D21 -> -0.062937563 | E23: =(E22-E21)/E21 -> 0.005992536 | F23: =(F22-F21)/F21 -> 0.012788491 | G23: =(G22-G21)/G21 -> -0.084018358 | H23: =(H22-H21)/H21 -> -0.1347893 | I23: =(I22-I21)/I21 -> -0.054180382 | J23: =(J22-J21)/J21 -> -0.04670382 | ... O23: =(O22-O21)/O21 -> -0.028727615
B24: 25年vs24年 | C24: =C22-C21 -> 0.31285983 | D24: =D22-D21 -> -0.68092836 | E24: =E22-E21 -> 0.060451194 | F24: =F22-F21 -> 0.1283147 | G24: =G22-G21 -> -0.93325495 | H24: =H22-H21 -> -1.6086424 | I24: =I22-I21 -> -0.59590587 | J24: =J22-J21 -> -0.51583059 | ... O24: =O22-O21 -> -0.30754135

Sheet 2025年老店营业额同比 环比分析
B2: 市场2025年老店营业额统计 | V2: 市场2024年老店营业额统计 | AM2: 市场老店24年&25年营业额同比 | BE2: 市场老店25年&24年营业额同比
B3: 直营门店 | C3: 1月 | D3: 2月 | E3: 3月 | F3: 4月 | G3: 5月 | H3: 6月 | I3: 7月 | J3: 8月 | K3: 9月 | L3: 10月 | M3: 11月 | N3: 12月 | O3: 合计 | P3: 11月日均 | Q3: 12月日均 | S3: 25年12月环比11月 | T3: 25&24年12月同比 | U3: 全年同比 | V3: 直营门店 | W3: 1月 | X3: 2月 | Y3: 3月 | Z3: 4月 | AA3: 5月 | AB3: 6月 | AC3: 7月 | AD3: 8月 | AE3: 9月 | AF3: 10月 | AG3: 11月 | AH3: 12月 | AI3: 合计 | AM3: 直营门店 | AN3: 1月 | AO3: 2月 | AP3: 3月 | AQ3: 4月 | AR3: 5月 | AS3: 6月 | AT3: 7月 | AU3: 8月 | AV3: 9月 | AW3: 10月 | AX3: 11月 | AY3: 12月 | AZ3: 合计 | BE3: 直营门店 | BF3: 1月 | BG3: 2月 | BH3: 3月 | BI3: 4月 | BJ3: 5月 | BK3: 6月 | BL3: 7月 | BM3: 8月 | BN3: 9月 | BO3: 10月 | BP3: 11月 | BQ3: 12月 | BR3: 合计
B5: 步行街店 | C5: 11.681857 | D5: 11.45976 | E5: 12.30345 | F5: 12.014886 | G5: 12.863619 | H5: 10.867187 | I5: 13.239522 | J5: 11.106115 | K5: 10.347582 | L5: 10.414614 | M5: 11.215678 | N5: 14.90469 | O5: =SUM(C5:N5) -> 142.41896 | P5: =M5/30 -> 0.37385593 | Q5: =N5/31 -> 0.48079645 | S5: =Q5-P5 -> 0.10694052 | T5: =N5/31-AH5/31 -> 0.092459355 | U5: =O5-AI5 -> -9.6321 | V5: 步行街店 | W5: 14.4085 | X5: 9.62105 | Y5: 14.78021 | Z5: 13.0491 | AA5: 13.4138 | AB5: 12.2205 | AC5: 15.50465 | AD5: 11.93295 | AE5: 11.21795 | AF5: 11.69975 | AG5: 12.16415 | AH5: 12.03845 | AI5: =SUM(W5:AH5) -> 152.05106 | AM5: 步行街店 | AN5: =(C5-W5)/W5 -> -0.18923851 | AO5: =(D5-X5)/X5 -> 0.19111324 | AP5: =(E5-Y5)/Y5 -> -0.16757272 | AQ5: =(F5-Z5)/Z5 -> -0.079255581 | AR5: =(G5-AA5)/AA5 -> -0.041016043 | AS5: =(H5-AB5)/AB5 -> -0.11074121 | AT5: =(I5-AC5)/AC5 -> -0.14609346 | AU5: =(J5-AD5)/AD5 -> -0.069290075 | ... AZ5: =(O5-AI5)/AI5 -> -0.063347799 | BE5: 步行街店 | BF5: =(C5-W5)/31 -> -0.087956226 | BG5: =(D5-X5)/28 -> 0.065668214 | BH5: =(E5-Y5)/31 -> -0.079895484 | BI5: =(F5-Z5)/30 -> -0.0344738 | BJ5: =(G5-AA5)/31 -> -0.017747774 | BK5: =(H5-AB5)/30 -> -0.045110433 | BL5: =(I5-AC5)/31 -> -0.073068645 | BM5: =(J5-AD5)/31 -> -0.026672097 | BN5: =(K5-AE5)/30 -> -0.029012267 | BO5: =L5-AF5 -> -1.285136 | BP5: =M5-AG5 -> -0.948472 | BQ5: =N5-AH5 -> 2.86624 | BR5: =O5-AI5 -> -9.6321
B6: 新常青十一小区店 | C6: 11.04901 | D6: 11.299986 | E6: 13.568962 | F6: 13.781852 | G6: 14.400119 | H6: 12.564223 | I6: 15.061661 | J6: 15.791372 | K6: 13.568442 | L6: 14.959915 | M6: 15.90785 | N6: 17.742376 | O6: =SUM(C6:N6) -> 169.69577 | P6: =M6/30 -> 0.53026167 | Q6: =N6/31 -> 0.57233471 | S6: =Q6-P6 -> 0.042073043 | T6: =N6/31-AH6/31 -> 0.15915406 | U6: =O6-AI6 -> 5.122368 | V6: 新常青十一小区店 | W6: 14.3526 | X6: 9.91865 | Y6: 14.92015 | Z6: 14.6463 | AA6: 14.6682 | AB6: 13.5356 | AC6: 16.11855 | AD6: 14.63585 | AE6: 12.81485 | AF6: 13.34445 | AG6: 12.8096 | AH6: 12.8086 | AI6: =SUM(W6:AH6) -> 164.5734 | AM6: 新常青十一小区店 | AN6: =(C6-W6)/W6 -> -0.23017363 | AO6: =(D6-X6)/X6 -> 0.13926653 | AP6: =(E6-Y6)/Y6 -> -0.090561288 | AQ6: =(F6-Z6)/Z6 -> -0.059021596 | AR6: =(G6-AA6)/AA6 -> -0.018276339 | AS6: =(H6-AB6)/AB6 -> -0.071764606 | AT6: =(I6-AC6)/AC6 -> -0.065569732 | AU6: =(J6-AD6)/AD6 -> 0.078951479 | ... AZ6: =(O6-AI6)/AI6 -> 0.031125127 | BE6: 新常青十一小区店 | BF6: =(C6-W6)/31 -> -0.10656742 | BG6: =(D6-X6)/28 -> 0.049333429 | BH6: =(E6-Y6)/31 -> -0.04358671 | BI6: =(F6-Z6)/30 -> -0.028814933 | BJ6: =(G6-AA6)/31 -> -0.0086477742 | BK6: =(H6-AB6)/30 -> -0.032379233 | BL6: =(I6-AC6)/31 -> -0.034093194 | BM6: =(J6-AD6)/31 -> 0.037274903 | BN6: =(K6-AE6)/30 -> 0.025119733 | BO6: =L6-AF6 -> 1.615465 | BP6: =M6-AG6 -> 3.09825 | BQ6: =N6-AH6 -> 4.933776 | BR6: =O6-AI6 -> 5.122368
B7: 新工厂店 | C7: 13.6025 | D7: 14.57995 | E7: 16.64905 | F7: 16.32602 | G7: 16.437079 | H7: 15.699708 | I7: 19.411293 | J7: 19.067524 | K7: 22.198704 | L7: 21.431654 | M7: 19.758887 | N7: 24.838165 | O7: =SUM(C7:N7) -> 220.00053 | P7: =M7/30 -> 0.65862957 | Q7: =N7/31 -> 0.80123113 | S7: =Q7-P7 -> 0.14260156 | T7: =N7/31-AH7/31 -> 0.25290855 | U7: =O7-AI7 -> 12.058464 | V7: 新工厂店 | W7: 17.08935 | X7: 12.0566 | Y7: 16.67135 | Z7: 16.14075 | AA7: 15.69295 | AB7: 18.98145 | AC7: 24.04402 | AD7: 21.61425 | AE7: 16.77995 | AF7: 16.08595 | AG7: 15.78745 | AH7: 16.998 | AI7: =SUM(W7:AH7) -> 207.94207 | AM7: 新工厂店 | AN7: =(C7-W7)/W7 -> -0.20403643 | AO7: =(D7-X7)/X7 -> 0.20929201 | AP7: =(E7-Y7)/Y7 -> -0.0013376241 | AQ7: =(F7-Z7)/Z7 -> 0.011478401 | AR7: =(G7-AA7)/AA7 -> 0.047418044 | AS7: =(H7-AB7)/AB7 -> -0.17289206 | AT7: =(I7-AC7)/AC7 -> -0.19267689 | AU7: =(J7-AD7)/AD7 -> -0.11782625 | ... AZ7: =(O7-AI7)/AI7 -> 0.057989535 | BE7: 新工厂店 | BF7: =(C7-W7)/31 -> -0.11247903 | BG7: =(D7-X7)/28 -> 0.090119643 | BH7: =(E7-Y7)/31 -> -0.00071935484 | BI7: =(F7-Z7)/30 -> 0.0061756667 | BJ7: =(G7-AA7)/31 -> 0.024004161 | BK7: =(H7-AB7)/30 -> -0.1093914 | BL7: =(I7-AC7)/31 -> -0.14944281 | BM7: =(J7-AD7)/31 -> -0.082152452 | BN7: =(K7-AE7)/30 -> 0.18062513 | BO7: =L7-AF7 -> 5.345704 | BP7: =M7-AG7 -> 3.971437 | BQ7: =N7-AH7 -> 7.840165 | BR7: =O7-AI7 -> 12.058464
B8: 光谷华科店 | C8: 43.624241 | D8: 41.759321 | E8: 47.286648 | F8: 44.105147 | G8: 44.125056 | H8: 42.968625 | I8: 50.883711 | J8: 52.430466 | K8: 47.556281 | L8: 47.29722 | M8: 46.491504 | N8: 49.768302 | O8: =SUM(C8:N8) -> 558.29652 | P8: =M8/30 -> 1.5497168 | Q8: =N8/31 -> 1.6054291 | S8: =Q8-P8 -> 0.055712297 | T8: =N8/31-AH8/31 -> -0.00059022581 | U8: =O8-AI8 -> 113.59115 | V8: 光谷华科店 | W8: 24.67212 | X8: 18.545 | Y8: 25.7533 | Z8: 25.13315 | AA8: 34.808626 | AB8: 34.240654 | AC8: 27.445889 | AD8: 56.69126 | AE8: 50.257394 | AF8: 49.386444 | AG8: 47.984938 | AH8: 49.786599 | AI8: =SUM(W8:AH8) -> 444.70537 | AM8: 光谷华科店 | AN8: =(C8-W8)/W8 -> 0.7681594 | AO8: =(D8-X8)/X8 -> 1.2517833 | AP8: =(E8-Y8)/Y8 -> 0.83613937 | AQ8: =(F8-Z8)/Z8 -> 0.7548595 | AR8: =(G8-AA8)/AA8 -> 0.26764716 | AS8: =(H8-AB8)/AB8 -> 0.25490083 | AT8: =(I8-AC8)/AC8 -> 0.85396476 | AU8: =(J8-AD8)/AD8 -> -0.075157864 | ... AZ8: =(O8-AI8)/AI8 -> 0.25543012 | BE8: 光谷华科店 | BF8: =(C8-W8)/31 -> 0.61135874 | BG8: =(D8-X8)/28 -> 0.82908289 | BH8: =(E8-Y8)/31 -> 0.69462413 | BI8: =(F8-Z8)/30 -> 0.6323999 | BJ8: =(G8-AA8)/31 -> 0.30053 | BK8: =(H8-AB8)/30 -> 0.29093237 | BL8: =(I8-AC8)/31 -> 0.75605877 | BM8: =(J8-AD8)/31 -> -0.13744497 | BN8: =(K8-AE8)/30 -> -0.0900371 | BO8: =L8-AF8 -> -2.089224 | BP8: =M8-AG8 -> -1.493434 | BQ8: =N8-AH8 -> -0.018297 | BR8: =O8-AI8 -> 113.59115
B9: 新华路店 | C9: 20.44439 | D9: 19.891771 | E9: 20.066298 | F9: 22.343034 | G9: 23.171114 | H9: 23.901958 | I9: 26.223891 | J9: 24.740977 | K9: 22.444834 | L9: 24.182829 | M9: 23.481845 | N9: 24.495947 | O9: =SUM(C9:N9) -> 275.38889 | P9: =M9/30 -> 0.78272817 | Q9: =N9/31 -> 0.79019184 | S9: =Q9-P9 -> 0.007463672 | T9: =N9/31-AH9/31 -> 0.068844742 | U9: =O9-AI9 -> 8.195708 | V9: 新华路店 | W9: 22.68776 | X9: 15.0936 | Y9: 22.4214 | Z9: 22.54322 | AA9: 24.2131 | AB9: 21.80981 | AC9: 23.321 | AD9: 23.48742 | AE9: 21.06856 | AF9: 24.55915 | AG9: 23.6264 | AH9: 22.36176 | AI9: =SUM(W9:AH9) -> 267.19318 | AM9: 新华路店 | AN9: =(C9-W9)/W9 -> -0.098880189 | AO9: =(D9-X9)/X9 -> 0.31789441 | AP9: =(E9-Y9)/Y9 -> -0.10503813 | AQ9: =(F9-Z9)/Z9 -> -0.0088800979 | AR9: =(G9-AA9)/AA9 -> -0.043033977 | AS9: =(H9-AB9)/AB9 -> 0.095926925 | AT9: =(I9-AC9)/AC9 -> 0.12447541 | AU9: =(J9-AD9)/AD9 -> 0.053371422 | ... AZ9: =(O9-AI9)/AI9 -> 0.030673343 | BE9: 新华路店 | BF9: =(C9-W9)/31 -> -0.072366774 | BG9: =(D9-X9)/28 -> 0.17136325 | BH9: =(E9-Y9)/31 -> -0.075971032 | BI9: =(F9-Z9)/30 -> -0.0066728667 | BJ9: =(G9-AA9)/31 -> -0.033612452 | BK9: =(H9-AB9)/30 -> 0.069738267 | BL9: =(I9-AC9)/31 -> 0.093641645 | BM9: =(J9-AD9)/31 -> 0.040437323 | BN9: =(K9-AE9)/30 -> 0.0458758 | BO9: =L9-AF9 -> -0.376321 | BP9: =M9-AG9 -> -0.144555 | BQ9: =N9-AH9 -> 2.134187 | BR9: =O9-AI9 -> 8.195708
B10: 合计 | C10: =SUM(C5:C9) -> 100.402 | D10: =SUM(D5:D9) -> 98.990788 | E10: =SUM(E5:E9) -> 109.87441 | F10: =SUM(F5:F9) -> 108.57094 | G10: =SUM(G5:G9) -> 110.99699 | H10: =SUM(H5:H9) -> 106.0017 | I10: =SUM(I5:I9) -> 124.82008 | J10: =SUM(J5:J9) -> 123.13645 | ... O10: =SUM(O5:O9) -> 1365.8007 | P10: =M10/30 -> 3.8951921 | Q10: =N10/31 -> 4.2499832 | S10: =Q10-P10 -> 0.35479109 | T10: =N10/31-AH10/31 -> 0.57277648 | U10: =O10-AI10 -> 129.33559 | V10: 合计 | W10: =SUM(W5:W9) -> 93.21033 | X10: =SUM(X5:X9) -> 65.2349 | Y10: =SUM(Y5:Y9) -> 94.54641 | Z10: =SUM(Z5:Z9) -> 91.51252 | AA10: =SUM(AA5:AA9) -> 102.79668 | AB10: =SUM(AB5:AB9) -> 100.78801 | AC10: =SUM(AC5:AC9) -> 106.43411 | AD10: =SUM(AD5:AD9) -> 128.36173 | ... AI10: =SUM(AI5:AI9) -> 1236.4651 | AM10: 合计 | AN10: =(C10-W10)/C10 -> 0.071628734 | AO10: =(D10-X10)/D10 -> 0.3410003 | AP10: =(E10-Y10)/E10 -> 0.13950472 | AQ10: =(F10-Z10)/F10 -> 0.15711773 | AR10: =(G10-AA10)/G10 -> 0.073878681 | AS10: =(H10-AB10)/H10 -> 0.049184937 | AT10: =(I10-AC10)/I10 -> 0.14729977 | AU10: =(J10-AD10)/J10 -> -0.042434842 | ... AY10: =(N10-AH10)/N10 -> 0.13477147 | AZ10: =(O10-AI10)/AI10 -> 0.10460108 | BE10: 合计 | BF10: =(C10-W10)/31 -> 0.23198929 | BG10: =(D10-X10)/28 -> 1.2055674 | BH10: =(E10-Y10)/31 -> 0.49445155 | BI10: =(F10-Z10)/30 -> 0.56861397 | BJ10: =(G10-AA10)/31 -> 0.26452616 | BK10: =(H10-AB10)/30 -> 0.17378957 | BL10: =(I10-AC10)/31 -> 0.59309577 | BM10: =(J10-AD10)/31 -> -0.16855729 | BN10: =(K10-AE10)/30 -> 0.1325713 | BO10: =L10-AF10 -> 3.210488 | BP10: =M10-AG10 -> 4.483226 | BQ10: =N10-AH10 -> 17.756071 | BR10: =O10-AI10 -> 129.33559
B11: 10000 | W11: 10000
B12: 市场2025年老店TC统计 | V12: 市场2024年老店TC统计 | AM12: 市场老店24年&25年TC同比 | BE12: 市场老店25年&24年TC同比
B13: 直营门店 | C13: 1月 | D13: 2月 | E13: 3月 | F13: 4月 | G13: 5月 | H13: 6月 | I13: 7月 | J13: 8月 | K13: 9月 | L13: 10月 | M13: 11月 | N13: 12月 | O13: 合计 | P13: 11月日均 | Q13: 12月日均 | S13: 25年12月环比11月 | T13: 25&24年12月同比 | U13: 全年同比 | V13: 直营门店 | W13: 1月 | X13: 2月 | Y13: 3月 | Z13: 4月 | AA13: 5月 | AB13: 6月 | AC13: 7月 | AD13: 8月 | AE13: 9月 | AF13: 10月 | AG13: 11月 | AH13: 12月 | AI13: 合计 | AM13: 直营门店 | AN13: 1月 | AO13: 2月 | AP13: 3月 | AQ13: 4月 | AR13: 5月 | AS13: 6月 | AT13: 7月 | AU13: 8月 | AV13: 9月 | AW13: 10月 | AX13: 11月 | AY13: 12月 | AZ13: 合计 | BE13: 直营门店 | BF13: 1月 | BG13: 2月 | BH13: 3月 | BI13: 4月 | BJ13: 5月 | BK13: 6月 | BL13: 7月 | BM13: 8月 | BN13: 9月 | BO13: 10月 | BP13: 11月 | BQ13: 12月 | BR13: 平均
B15: 步行街店 | C15: 1.2497 | D15: 1.207 | E15: 1.3272 | F15: 1.3067 | G15: 1.3748 | H15: 1.1699 | I15: 1.4154 | J15: 1.1762 | K15: 1.1573 | L15: 1.1137 | M15: 1.1929 | N15: 1.5454 | O15: =SUM(C15:N15) -> 15.2362 | P15: =M15/30 -> 0.039763333 | Q15: =N15/31 -> 0.049851613 | S15: =Q15-P15 -> 0.01008828 | T15: =N15/31-AH15/31 -> 0.0078483871 | U15: =O15-AI15 -> -0.9849 | V15: 步行街店 | W15: 1.538 | X15: 0.9512 | Y15: 1.5719 | Z15: 1.4016 | AA15: 1.4277 | AB15: 1.3032 | AC15: 1.6197 | AD15: =(3199+9616)/10000 -> 1.2815 | AE15: 1.2361 | AF15: 1.261 | AG15: 1.3271 | AH15: 1.3021 | AI15: =SUM(W15:AH15) -> 16.2211 | AM15: 步行街店 | AN15: =(C15-W15)/W15 -> -0.18745124 | AO15: =(D15-X15)/X15 -> 0.26892347 | AP15: =(E15-Y15)/Y15 -> -0.15567148 | AQ15: =(F15-Z15)/Z15 -> -0.067708333 | AR15: =(G15-AA15)/AA15 -> -0.037052602 | AS15: =(H15-AB15)/AB15 -> -0.10228668 | AT15: =(I15-AC15)/AC15 -> -0.12613447 | AU15: =(J15-AD15)/AD15 -> -0.082169333 | ... AZ15: =(O15-AI15)/AI15 -> -0.060717214 | BE15: 步行街店 | BF15: =(C15-W15)/31 -> -0.0093 | BG15: =(D15-X15)/28 -> 0.0091357143 | BH15: =(E15-Y15)/31 -> -0.0078935484 | BI15: =(F15-Z15)/30 -> -0.0031633333 | BJ15: =(G15-AA15)/31 -> -0.0017064516 | BK15: =(H15-AB15)/30 -> -0.0044433333 | BL15: =(I15-AC15)/31 -> -0.0065903226 | BM15: =(J15-AD15)/31 -> -0.0033967742 | BN15: =(K15-AE15)/30 -> -0.0026266667 | BO15: =L15-AF15 -> -0.1473 | BP15: =M15-AG15 -> -0.1342 | BQ15: =N15-AH15 -> 0.2433 | BR15: =AVERAGE(BF15:BN15) -> -0.0033316351
B16: 新常青十一小区店 | C16: 1.0442 | D16: 1.0626 | E16: 1.3161 | F16: 1.3107 | G16: 1.3683 | H16: 1.1965 | I16: 1.4173 | J16: 1.462 | K16: 1.318 | L16: 1.3892 | M16: 1.4517 | N16: 1.5391 | O16: =SUM(C16:N16) -> 15.8757 | P16: =M16/30 -> 0.04839 | Q16: =N16/31 -> 0.049648387 | S16: =Q16-P16 -> 0.0012583871 | T16: =N16/31-AH16/31 -> 0.010367742 | U16: =O16-AI16 -> 0.4621 | V16: 新常青十一小区店 | W16: 1.3919 | X16: 0.8403 | Y16: 1.385 | Z16: 1.4007 | AA16: 1.3708 | AB16: 1.2715 | AC16: =(4838+10027)/10000 -> 1.4865 | AD16: 1.3364 | AE16: 1.237 | AF16: 1.2596 | AG16: 1.2162 | AH16: 1.2177 | AI16: =SUM(W16:AH16) -> 15.4136 | AM16: 新常青十一小区店 | AN16: =(C16-W16)/W16 -> -0.24980243 | AO16: =(D16-X16)/X16 -> 0.26454838 | AP16: =(E16-Y16)/Y16 -> -0.049747292 | AQ16: =(F16-Z16)/Z16 -> -0.064253587 | AR16: =(G16-AA16)/AA16 -> -0.0018237526 | AS16: =(H16-AB16)/AB16 -> -0.05898545 | AT16: =(I16-AC16)/AC16 -> -0.046552304 | AU16: =(J16-AD16)/AD16 -> 0.093983837 | ... AZ16: =(O16-AI16)/AI16 -> 0.029980018 | BE16: 新常青十一小区店 | BF16: =(C16-W16)/31 -> -0.011216129 | BG16: =(D16-X16)/28 -> 0.0079392857 | BH16: =(E16-Y16)/31 -> -0.0022225806 | BI16: =(F16-Z16)/30 -> -0.003 | BJ16: =(G16-AA16)/31 -> -8.0645161e-05 | BK16: =(H16-AB16)/30 -> -0.0025 | BL16: =(I16-AC16)/31 -> -0.0022322581 | BM16: =(J16-AD16)/31 -> 0.0040516129 | BN16: =(K16-AE16)/30 -> 0.0027 | BO16: =L16-AF16 -> 0.1296 | BP16: =M16-AG16 -> 0.2355 | BQ16: =N16-AH16 -> 0.3214 | BR16: =AVERAGE(BF16:BN16) -> -0.00072896825
B17: 新工厂店 | C17: 1.3474 | D17: 1.4603 | E17: 1.6576 | F17: 1.6853 | G17: 1.708 | H17: 1.6449 | I17: 2.0084 | J17: 1.9812 | K17: 2.1867 | L17: 2.0487 | M17: 1.9074 | N17: 2.2718 | O17: =SUM(C17:N17) -> 21.9077 | P17: =M17/30 -> 0.06358 | Q17: =N17/31 -> 0.073283871 | S17: =Q17-P17 -> 0.009703871 | T17: =N17/31-AH17/31 -> 0.019480645 | U17: =O17-AI17 -> 2.4571 | V17: 新工厂店 | W17: 1.698 | X17: 1.091 | Y17: 1.6274 | Z17: 1.5584 | AA17: 1.5517 | AB17: 1.6283 | AC17: 2.0184 | AD17: =(7323+12588)/10000 -> 1.9911 | AE17: 1.6066 | AF17: 1.5106 | AG17: 1.5012 | AH17: 1.6679 | AI17: =SUM(W17:AH17) -> 19.4506 | AM17: 新工厂店 | AN17: =(C17-W17)/W17 -> -0.20647821 | AO17: =(D17-X17)/X17 -> 0.33849679 | AP17: =(E17-Y17)/Y17 -> 0.018557208 | AQ17: =(F17-Z17)/Z17 -> 0.081429671 | AR17: =(G17-AA17)/AA17 -> 0.10072823 | AS17: =(H17-AB17)/AB17 -> 0.010194682 | AT17: =(I17-AC17)/AC17 -> -0.0049544193 | AU17: =(J17-AD17)/AD17 -> -0.004972126 | ... AZ17: =(O17-AI17)/AI17 -> 0.12632515 | BE17: 新工厂店 | BF17: =(C17-W17)/31 -> -0.011309677 | BG17: =(D17-X17)/28 -> 0.013189286 | BH17: =(E17-Y17)/31 -> 0.00097419355 | BI17: =(F17-Z17)/30 -> 0.00423 | BJ17: =(G17-AA17)/31 -> 0.0050419355 | BK17: =(H17-AB17)/30 -> 0.00055333333 | BL17: =(I17-AC17)/31 -> -0.00032258065 | BM17: =(J17-AD17)/31 -> -0.00031935484 | BN17: =(K17-AE17)/30 -> 0.019336667 | BO17: =L17-AF17 -> 0.5381 | BP17: =M17-AG17 -> 0.4062 | BQ17: =N17-AH17 -> 0.6039 | BR17: =AVERAGE(BF17:BN17) -> 0.003485978
B18: 光谷华科店 | C18: 3.7244 | D18: 3.6513 | E18: 4.0369 | F18: 3.7831 | G18: 3.7946 | H18: 3.6574 | I18: 4.3626 | J18: 4.4063 | K18: 4.0603 | L18: 3.8598 | M18: 3.8259 | N18: 4.0713 | O18: =SUM(C18:N18) -> 47.2339 | P18: =M18/30 -> 0.12753 | Q18: =N18/31 -> 0.13133226 | S18: =Q18-P18 -> 0.0038022581 | T18: =N18/31-AH18/31 -> -0.0051677419 | U18: =O18-AI18 -> 9.9606 | V18: 光谷华科店 | W18: 2.3552 | X18: 1.6977 | Y18: 2.4888 | Z18: 2.4351 | AA18: 2.4336 | AB18: 2.0452 | AC18: 2.2413 | AD18: =(12202+34965)/10000 -> 4.7167 | AE18: 4.3089 | AF18: 4.2109 | AG18: 4.1084 | AH18: 4.2315 | AI18: =SUM(W18:AH18) -> 37.2733 | AM18: 光谷华科店 | AN18: =(C18-W18)/W18 -> 0.5813519 | AO18: =(D18-X18)/X18 -> 1.1507333 | AP18: =(E18-Y18)/Y18 -> 0.62202668 | AQ18: =(F18-Z18)/Z18 -> 0.5535707 | AR18: =(G18-AA18)/AA18 -> 0.55925378 | AS18: =(H18-AB18)/AB18 -> 0.78828476 | AT18: =(I18-AC18)/AC18 -> 0.94645964 | AU18: =(J18-AD18)/AD18 -> -0.065808722 | ... AZ18: =(O18-AI18)/AI18 -> 0.2672315 | BE18: 光谷华科店 | BF18: =(C18-W18)/31 -> 0.044167742 | BG18: =(D18-X18)/28 -> 0.069771429 | BH18: =(E18-Y18)/31 -> 0.04993871 | BI18: =(F18-Z18)/30 -> 0.044933333 | BJ18: =(G18-AA18)/31 -> 0.043903226 | BK18: =(H18-AB18)/30 -> 0.05374 | BL18: =(I18-AC18)/31 -> 0.068429032 | BM18: =(J18-AD18)/31 -> -0.010012903 | BN18: =(K18-AE18)/30 -> -0.0082866667 | BO18: =L18-AF18 -> -0.3511 | BP18: =M18-AG18 -> -0.2825 | BQ18: =N18-AH18 -> -0.1602 | BR18: =AVERAGE(BF18:BN18) -> 0.039620434
B19: 新华路店 | C19: 2.0531 | D19: 2.0444 | E19: 2.1216 | F19: 2.3083 | G19: 2.378 | H19: 2.367 | I19: 2.5446 | J19: 2.3634 | K19: 2.2797 | L19: 2.3051 | M19: 2.2442 | N19: 2.3284 | O19: =SUM(C19:N19) -> 27.3378 | P19: =M19/30 -> 0.074806667 | Q19: =N19/31 -> 0.075109677 | S19: =Q19-P19 -> 0.00030301075 | T19: =N19/31-AH19/31 -> 0.0026677419 | U19: =O19-AI19 -> 0.5399 | V19: 新华路店 | W19: 2.2345 | X19: 1.4494 | Y19: 2.2993 | Z19: 2.3248 | AA19: 2.4707 | AB19: 2.1969 | AC19: 2.3112 | AD19: =(6496+16467)/10000 -> 2.2963 | AE19: 2.1707 | AF19: 2.4228 | AG19: 2.3756 | AH19: 2.2457 | AI19: =SUM(W19:AH19) -> 26.7979 | AM19: 新华路店 | AN19: =(C19-W19)/W19 -> -0.081181472 | AO19: =(D19-X19)/X19 -> 0.4105147 | AP19: =(E19-Y19)/Y19 -> -0.077284391 | AQ19: =(F19-Z19)/Z19 -> -0.0070973847 | AR19: =(G19-AA19)/AA19 -> -0.037519731 | AS19: =(H19-AB19)/AB19 -> 0.077427284 | AT19: =(I19-AC19)/AC19 -> 0.1009865 | AU19: =(J19-AD19)/AD19 -> 0.029220921 | ... AZ19: =(O19-AI19)/AI19 -> 0.020147101 | BE19: 新华路店 | BF19: =(C19-W19)/31 -> -0.0058516129 | BG19: =(D19-X19)/28 -> 0.02125 | BH19: =(E19-Y19)/31 -> -0.0057322581 | BI19: =(F19-Z19)/30 -> -0.00055 | BJ19: =(G19-AA19)/31 -> -0.0029903226 | BK19: =(H19-AB19)/30 -> 0.00567 | BL19: =(I19-AC19)/31 -> 0.0075290323 | BM19: =(J19-AD19)/31 -> 0.0021645161 | BN19: =(K19-AE19)/30 -> 0.0036333333 | BO19: =L19-AF19 -> -0.1177 | BP19: =M19-AG19 -> -0.1314 | BQ19: =N19-AH19 -> 0.0827 | BR19: =AVERAGE(BF19:BN19) -> 0.0027914098
B20: 合计 | C20: =SUM(C15:C19) -> 9.4188 | D20: =SUM(D15:D19) -> 9.4256 | E20: =SUM(E15:E19) -> 10.4594 | F20: =SUM(F15:F19) -> 10.3941 | G20: =SUM(G15:G19) -> 10.6237 | H20: =SUM(H15:H19) -> 10.0357 | I20: =SUM(I15:I19) -> 11.7483 | J20: =SUM(J15:J19) -> 11.3891 | ... O20: =SUM(O15:O19) -> 127.5913 | P20: =M20/30 -> 0.35407 | Q20: =N20/31 -> 0.37922581 | S20: =Q20-P20 -> 0.025155806 | T20: =N20/31-AH20/31 -> 0.035196774 | U20: =O20-AI20 -> 12.4348 | V20: 合计 | W20: =SUM(W15:W19) -> 9.2176 | X20: =SUM(X15:X19) -> 6.0296 | Y20: =SUM(Y15:Y19) -> 9.3724 | Z20: =SUM(Z15:Z19) -> 9.1206 | AA20: =SUM(AA15:AA19) -> 9.2545 | AB20: =SUM(AB15:AB19) -> 8.4451 | AC20: =SUM(AC15:AC19) -> 9.6771 | AD20: =SUM(AD15:AD19) -> 11.622 | ... AI20: =SUM(AI15:AI19) -> 115.1565 | AM20: 合计 | AN20: =(C20-W20)/C20 -> 0.021361532 | AO20: =(D20-X20)/D20 -> 0.36029537 | AP20: =(E20-Y20)/E20 -> 0.10392566 | AQ20: =(F20-Z20)/F20 -> 0.12252143 | AR20: =(G20-AA20)/G20 -> 0.12888165 | AS20: =(H20-AB20)/H20 -> 0.15849418 | AT20: =(I20-AC20)/I20 -> 0.17629785 | AU20: =(J20-AD20)/J20 -> -0.020449377 | ... AY20: =(N20-AH20)/N20 -> 0.092812181 | AZ20: =(O20-AI20)/AI20 -> 0.10798175 | BE20: 合计 | BF20: =(C20-W20)/31 -> 0.0064903226 | BG20: =(D20-X20)/28 -> 0.12128571 | BH20: =(E20-Y20)/31 -> 0.035064516 | BI20: =(F20-Z20)/30 -> 0.04245 | BJ20: =(G20-AA20)/31 -> 0.044167742 | BK20: =(H20-AB20)/30 -> 0.05302 | BL20: =(I20-AC20)/31 -> 0.066812903 | BM20: =(J20-AD20)/31 -> -0.0075129032 | BN20: =(K20-AE20)/30 -> 0.014756667 | BO20: =L20-AF20 -> 0.0516 | BP20: =M20-AG20 -> 0.0936 | BQ20: =N20-AH20 -> 1.0911 | BR20: =AVERAGE(BF20:BN20) -> 0.041837218
B22: 市场2025年老店AC统计 | V22: 市场2024年老店AC统计 | AM22: 市场老店24年&25年AC同比 | BE22: 市场老店25年&24年AC同比
B23: 直营门店 | C23: 1月 | D23: 2月 | E23: 3月 | F23: 4月 | G23: 5月 | H23: 6月 | I23: 7月 | J23: 8月 | K23: 9月 | L23: 10月 | M23: 11月 | N23: 12月 | O23: 合计 | P23: 25年12月 环比11月 | Q23: 25&24年 12月同比 | S23: 全年同比 | V23: 直营门店 | W23: 1月 | X23: 2月 | Y23: 3月 | Z23: 4月 | AA23: 5月 | AB23: 6月 | AC23: 7月 | AD23: 8月 | AE23: 9月 | AF23: 10月 | AG23: 11月 | AH23: 12月 | AI23: 合计 | AM23: 直营门店 | AN23: 1月 | AO23: 2月 | AP23: 3月 | AQ23: 4月 | AR23: 5月 | AS23: 6月 | AT23: 7月 | AU23: 8月 | AV23: 9月 | AW23: 10月 | AX23: 11月 | AY23: 12月 | AZ23: 合计 | BE23: 直营门店 | BF23: 1月 | BG23: 2月 | BH23: 3月 | BI23: 4月 | BJ23: 5月 | BK23: 6月 | BL23: 7月 | BM23: 8月 | BN23: 9月 | BO23: 10月 | BP23: 11月 | BQ23: 12月 | BR23: 平均
B25: 步行街店 | C25: =C5/C15 -> 9.3477291 | D25: =D5/D15 -> 9.4944159 | E25: =E5/E15 -> 9.2702306 | F25: =F5/F15 -> 9.1948313 | G25: =G5/G15 -> 9.3567203 | H25: =H5/H15 -> 9.2889879 | I25: =I5/I15 -> 9.3539084 | J25: =J5/J15 -> 9.4423695 | K25: =K5/K15 -> 8.9411406 | L25: 9.3513639 | M25: 9.402027 | N25: 9.6445516 | O25: =O5/O15 -> 9.3474068 | P25: =N25-M25 -> 0.24252458 | Q25: =N25-AH25 -> 0.39914031 | S25: =O25-AI25 -> -0.026252166 | V25: 步行街店 | W25: =W5/W15 -> 9.3683355 | X25: =X5/X15 -> 10.114645 | Y25: =Y5/Y15 -> 9.4027674 | Z25: =Z5/Z15 -> 9.3101455 | AA25: =AA5/AA15 -> 9.3953912 | AB25: =AB5/AB15 -> 9.377302 | AC25: =AC5/AC15 -> 9.5725443 | AD25: =AD5/AD15 -> 9.311705 | AE25: =AE5/AE15 -> 9.0752771 | AF25: 9.2781523 | AG25: 9.1659634 | AH25: 9.2454113 | AI25: =AI5/AI15 -> 9.373659 | AM25: 步行街店 | AN25: =C25-W25 -> -0.020606446 | AO25: =D25-X25 -> -0.62022875 | AP25: =E25-Y25 -> -0.13253679 | AQ25: =F25-Z25 -> -0.11531429 | AR25: =G25-AA25 -> -0.038670938 | AS25: =H25-AB25 -> -0.088314078 | AT25: =I25-AC25 -> -0.21863586 | AU25: =J25-AD25 -> 0.13066446 | ... AZ25: =O25-AI25 -> -0.026252166 | BE25: 步行街店 | BF25: =W25-C25 -> 0.020606446 | BG25: =X25-D25 -> 0.62022875 | BH25: =Y25-E25 -> 0.13253679 | BI25: =Z25-F25 -> 0.11531429 | BJ25: =AA25-G25 -> 0.038670938 | BK25: =AB25-H25 -> 0.088314078 | BL25: =AC25-I25 -> 0.21863586 | BM25: =AD25-J25 -> -0.13066446 | ... BQ25: =AH25-N25 -> -0.39914031 | BR25: =AVERAGE(BF25:BQ25) -> 0.044113634
B26: 新常青十一小区店 | C26: =C6/C16 -> 10.581316 | D26: =D6/D16 -> 10.63428 | E26: =E6/E16 -> 10.309978 | F26: =F6/F16 -> 10.514879 | G26: =G6/G16 -> 10.524095 | H26: =H6/H16 -> 10.500813 | I26: =I6/I16 -> 10.62701 | J26: =J6/J16 -> 10.801212 | K26: =K6/K16 -> 10.294721 | L26: 10.768727 | M26: 10.958084 | N26: 11.52776 | O26: =O6/O16 -> 10.689026 | P26: =N26-M26 -> 0.56967675 | Q26: =N26-AH26 -> 1.0090776 | S26: =O26-AI26 -> 0.01187063 | V26: 新常青十一小区店 | W26: =W6/W16 -> 10.311517 | X26: =X6/X16 -> 11.803701 | Y26: =Y6/Y16 -> 10.772671 | Z26: =Z6/Z16 -> 10.456415 | AA26: =AA6/AA16 -> 10.700467 | AB26: =AB6/AB16 -> 10.645379 | AC26: =AC6/AC16 -> 10.84329 | AD26: =AD6/AD16 -> 10.951699 | AE26: =AE6/AE16 -> 10.35962 | AF26: 10.594197 | AG26: 10.532478 | AH26: 10.518683 | AI26: =AI6/AI16 -> 10.677155 | AM26: 新常青十一小区店 | AN26: =C26-W26 -> 0.26979921 | AO26: =D26-X26 -> -1.169421 | AP26: =E26-Y26 -> -0.46269351 | AQ26: =F26-Z26 -> 0.058464422 | AR26: =G26-AA26 -> -0.17637202 | AS26: =H26-AB26 -> -0.14456627 | AT26: =I26-AC26 -> -0.2162798 | AU26: =J26-AD26 -> -0.15048655 | ... AZ26: =O26-AI26 -> 0.01187063 | BE26: 新常青十一小区店 | BF26: =W26-C26 -> -0.26979921 | BG26: =X26-D26 -> 1.169421 | BH26: =Y26-E26 -> 0.46269351 | BI26: =Z26-F26 -> -0.058464422 | BJ26: =AA26-G26 -> 0.17637202 | BK26: =AB26-H26 -> 0.14456627 | BL26: =AC26-I26 -> 0.2162798 | BM26: =AD26-J26 -> 0.15048655 | ... BQ26: =AH26-N26 -> -1.0090776 | BR26: =AVERAGE(BF26:BQ26) -> 0.037270142
B27: 新工厂店 | C27: =C7/C17 -> 10.095369 | D27: =D7/D17 -> 9.9842156 | E27: =E7/E17 -> 10.04407 | F27: =F7/F17 -> 9.6873079 | G27: =G7/G17 -> 9.6235826 | H27: =H7/H17 -> 9.5444757 | I27: =I7/I17 -> 9.6650533 | J27: =J7/J17 -> 9.6242298 | K27: =K7/K17 -> 10.151692 | L27: 10.461099 | M27: 10.359068 | N27: 10.933253 | O27: =O7/O17 -> 10.042156 | P27: =N27-M27 -> 0.574185 | Q27: =N27-AH27 -> 0.7419949 | S27: =O27-AI27 -> -0.64862352 | V27: 新工厂店 | W27: =W7/W17 -> 10.064399 | X27: =X7/X17 -> 11.050962 | Y27: =Y7/Y17 -> 10.244162 | Z27: =Z7/Z17 -> 10.357257 | AA27: =AA7/AA17 -> 10.113392 | AB27: =AB7/AB17 -> 11.657219 | AC27: =AC7/AC17 -> 11.912416 | AD27: =AD7/AD17 -> 10.855432 | AE27: =AE7/AE17 -> 10.444386 | AF27: 10.648716 | AG27: 10.516553 | AH27: 10.191258 | AI27: =AI7/AI17 -> 10.690779 | AM27: 新工厂店 | AN27: =C27-W27 -> 0.030969565 | AO27: =D27-X27 -> -1.0667468 | AP27: =E27-Y27 -> -0.20009273 | AQ27: =F27-Z27 -> -0.66994955 | AR27: =G27-AA27 -> -0.48980921 | AS27: =H27-AB27 -> -2.1127435 | AT27: =I27-AC27 -> -2.2473625 | AU27: =J27-AD27 -> -1.2312019 | ... AZ27: =O27-AI27 -> -0.64862352 | BE27: 新工厂店 | BF27: =W27-C27 -> -0.030969565 | BG27: =X27-D27 -> 1.0667468 | BH27: =Y27-E27 -> 0.20009273 | BI27: =Z27-F27 -> 0.66994955 | BJ27: =AA27-G27 -> 0.48980921 | BK27: =AB27-H27 -> 2.1127435 | BL27: =AC27-I27 -> 2.2473625 | BM27: =AD27-J27 -> 1.2312019 | ... BQ27: =AH27-N27 -> -0.7419949 | BR27: =AVERAGE(BF27:BQ27) -> 0.65689479
B28: 光谷华科店 | C28: =C8/C18 -> 11.713092 | D28: =D8/D18 -> 11.436836 | E28: =E8/E18 -> 11.713604 | F28: =F8/F18 -> 11.658467 | G28: =G8/G18 -> 11.628381 | H28: =H8/H18 -> 11.748407 | I28: =I8/I18 -> 11.663621 | J28: =J8/J18 -> 11.898978 | K28: =K8/K18 -> 11.712504 | L28: 12.253801 | M28: 12.151782 | N28: 12.22418 | O28: =O8/O18 -> 11.819827 | P28: =N28-M28 -> 0.072397175 | Q28: =N28-AH28 -> 0.45847018 | S28: =O28-AI28 -> -0.11110956 | V28: 光谷华科店 | W28: =W8/W18 -> 10.475594 | X28: =X8/X18 -> 10.923603 | Y28: =Y8/Y18 -> 10.347678 | Z28: =Z8/Z18 -> 10.321198 | AA28: =AA8/AA18 -> 14.303347 | AB28: =AB8/AB18 -> 16.741959 | AC28: =AC8/AC18 -> 12.245522 | AD28: =AD8/AD18 -> 12.019263 | AE28: =AE8/AE18 -> 11.663625 | AF28: 11.72824 | AG28: 11.679714 | AH28: 11.765709 | AI28: =AI8/AI18 -> 11.930936 | AM28: 光谷华科店 | AN28: =C28-W28 -> 1.2374979 | AO28: =D28-X28 -> 0.51323395 | AP28: =E28-Y28 -> 1.3659264 | AQ28: =F28-Z28 -> 1.3372688 | AR28: =G28-AA28 -> -2.6749659 | AS28: =H28-AB28 -> -4.9935514 | AT28: =I28-AC28 -> -0.58190169 | AU28: =J28-AD28 -> -0.12028564 | ... AZ28: =O28-AI28 -> -0.11110956 | BE28: 光谷华科店 | BF28: =W28-C28 -> -1.2374979 | BG28: =X28-D28 -> -0.51323395 | BH28: =Y28-E28 -> -1.3659264 | BI28: =Z28-F28 -> -1.3372688 | BJ28: =AA28-G28 -> 2.6749659 | BK28: =AB28-H28 -> 4.9935514 | BL28: =AC28-I28 -> 0.58190169 | BM28: =AD28-J28 -> 0.12028564 | ... BQ28: =AH28-N28 -> -0.45847018 | BR28: =AVERAGE(BF28:BQ28) -> 0.20098325
B29: 新华路店 | C29: =C9/C19 -> 9.957815 | D29: =D9/D19 -> 9.7298821 | E29: =E9/E19 -> 9.4580967 | F29: =F9/F19 -> 9.6794325 | G29: =G9/G19 -> 9.7439504 | H29: =H9/H19 -> 10.097997 | I29: =I9/I19 -> 10.305703 | J29: =J9/J19 -> 10.468383 | K29: =K9/K19 -> 9.8455209 | L29: 10.491011 | M29: 10.463348 | N29: 10.520506 | O29: =O9/O19 -> 10.073557 | P29: =N29-M29 -> 0.057158615 | Q29: =N29-AH29 -> 0.5629163 | S29: =O29-AI29 -> 0.10288099 | V29: 新华路店 | W29: =W9/W19 -> 10.153394 | X29: =X9/X19 -> 10.413688 | Y29: =Y9/Y19 -> 9.7514026 | Z29: =Z9/Z19 -> 9.6968427 | AA29: =AA9/AA19 -> 9.8000971 | AB29: =AB9/AB19 -> 9.9275388 | AC29: =AC9/AC19 -> 10.090429 | AD29: =AD9/AD19 -> 10.228376 | AE29: =AE9/AE19 -> 9.7058829 | AF29: 10.136681 | AG29: 9.9454454 | AH29: 9.9575901 | AI29: =AI9/AI19 -> 9.9706761 | AM29: 新华路店 | AN29: =C29-W29 -> -0.19557948 | AO29: =D29-X29 -> -0.68380631 | AP29: =E29-Y29 -> -0.29330588 | AQ29: =F29-Z29 -> -0.017410256 | AR29: =G29-AA29 -> -0.05614676 | AS29: =H29-AB29 -> 0.17045782 | AT29: =I29-AC29 -> 0.21527345 | AU29: =J29-AD29 -> 0.24000718 | ... AZ29: =O29-AI29 -> 0.10288099 | BE29: 新华路店 | BF29: =W29-C29 -> 0.19557948 | BG29: =X29-D29 -> 0.68380631 | BH29: =Y29-E29 -> 0.29330588 | BI29: =Z29-F29 -> 0.017410256 | BJ29: =AA29-G29 -> 0.05614676 | BK29: =AB29-H29 -> -0.17045782 | BL29: =AC29-I29 -> -0.21527345 | BM29: =AD29-J29 -> -0.24000718 | ... BQ29: =AH29-N29 -> -0.5629163 | BR29: =AVERAGE(BF29:BQ29) -> -0.079523045
B30: 合计 | C30: =C10/C20 -> 10.659744 | D30: =D10/D20 -> 10.502333 | E30: =E10/E20 -> 10.504848 | F30: =F10/F20 -> 10.445439 | G30: =G10/G20 -> 10.448054 | H30: =H10/H20 -> 10.562462 | I30: =I10/I20 -> 10.624523 | J30: =J10/J20 -> 10.811781 | ... O30: =O10/O20 -> 10.704497 | P30: =N30-M30 -> 0.20580675 | Q30: =N30-AH30 -> 0.51834658 | S30: =O30-AI30 -> -0.032761414 | V30: 合计 | W30: =W10/W20 -> 10.112213 | X30: =X10/X20 -> 10.819109 | Y30: =Y10/Y20 -> 10.087748 | Z30: =Z10/Z20 -> 10.033607 | AA30: =AA10/AA20 -> 11.10775 | AB30: =AB10/AB20 -> 11.934496 | AC30: =AC10/AC20 -> 10.998554 | AD30: =AD10/AD20 -> 11.044719 | ... AI30: =AI10/AI20 -> 10.737258 | AM30: 合计 | AN30: =C30-W30 -> 0.54753162 | AO30: =D30-X30 -> -0.31677627 | AP30: =E30-Y30 -> 0.41710001 | AQ30: =F30-Z30 -> 0.41183171 | AR30: =G30-AA30 -> -0.65969679 | AS30: =H30-AB30 -> -1.3720341 | AT30: =I30-AC30 -> -0.37403169 | AU30: =J30-AD30 -> -0.23293858 | ... AZ30: =O30-AI30 -> -0.032761414 | BE30: 合计 | BF30: =W30-C30 -> -0.54753162 | BG30: =X30-D30 -> 0.31677627 | BH30: =Y30-E30 -> -0.41710001 | BI30: =Z30-F30 -> -0.41183171 | BJ30: =AA30-G30 -> 0.65969679 | BK30: =AB30-H30 -> 1.3720341 | BL30: =AC30-I30 -> 0.37403169 | BM30: =AD30-J30 -> 0.23293858 | ... BQ30: =AH30-N30 -> -0.51834658 | BR30: =AVERAGE(BF30:BQ30) -> 0.045904606

Sheet 25年新店营业额环比分析
B2: 市场2025年新店营业额统计 | T2: 市场2024年营业额统计
B3: 直营门店 | C3: 1月 | D3: 2月 | E3: 3月 | F3: 4月 | G3: 5月 | H3: 6月 | I3: 7月 | J3: 8月 | K3: 9月 | L3: 10月 | M3: 11月 | N3: 12月 | O3: 合计 | P3: 12月日均环比11月 | Q3: 12月日均环比11月日均 | R3: 12月同比 | T3: 直营门店 | U3: 1月 | V3: 2月 | W3: 3月 | X3: 4月 | Y3: 5月 | Z3: 6月 | AA3: 7月 | AB3: 8月 | AC3: 9月 | AD3: 10月 | AE3: 11月 | AF3: 12月 | AG3: 合计
B5: 铁机路店 | D5: 100046.3 | E5: 155780.9 | F5: 142137 | G5: 146108.97 | H5: 132483.6 | I5: 149499.94 | J5: 165453.41 | K5: 138580.53 | L5: 168507.58 | M5: 154397.71 | N5: 181054.89 | O5: =SUM(C5:N5) -> 1634050.8 | P5: =(N5/31-M5/30)/(M5/30) -> 0.13482518 | Q5: =N5/31-M5/30 -> 693.88999 | AG5: =SUM(U5:AF5) -> 0
B6: 蔡甸中百店 | C6: 81907.68 | D6: 74101.59 | E6: 71806.2 | F6: 69853.38 | G6: 80565.41 | H6: 75347.44 | I6: 84769.78 | J6: 87358.71 | K6: 88786.64 | L6: 101017.03 | M6: 100960.95 | N6: 120447.8 | O6: =SUM(C6:N6) -> 1036922.6 | P6: =(N6/31-M6/30)/(M6/30) -> 0.15452942 | Q6: =N6/31-M6/30 -> 520.0479 | R6: =N6/31-AF6/31 -> 909.54194 | AE6: 105369.3 | AF6: 92252 | AG6: =SUM(U6:AF6) -> 197621.3
B7: 东辉花园店 | E7: 41818.6 | F7: 127459 | G7: 115459.74 | H7: 124882.46 | I7: 147010.74 | J7: 135766.6 | K7: 110654.46 | L7: 119567.89 | M7: 112993.01 | N7: 138818.92 | O7: =SUM(C7:N7) -> 1174431.4 | P7: =(N7/31-M7/30)/(M7/30) -> 0.18893098 | Q7: =N7/31-M7/30 -> 711.59601 | AG7: =SUM(U7:AF7) -> 0
B8: 合计 | C8: =SUM(C5:C7) -> 81907.68 | D8: =SUM(D5:D7) -> 174147.89 | E8: =SUM(E5:E7) -> 269405.7 | F8: =SUM(F5:F7) -> 339449.38 | G8: =SUM(G5:G7) -> 342134.12 | H8: =SUM(H5:H7) -> 332713.5 | I8: =SUM(I5:I7) -> 381280.46 | J8: =SUM(J5:J7) -> 388578.72 | ... O8: =SUM(O5:O7) -> 3845404.9 | P8: =(N8/31-M8/30)/(M8/30) -> 0.15682301 | Q8: =N8/31-M8/30 -> 1925.5339 | T8: 合计 | U8: =SUM(U5:U7) -> 0 | V8: =SUM(V5:V7) -> 0 | W8: =SUM(W5:W7) -> 0 | X8: =SUM(X5:X7) -> 0 | Y8: =SUM(Y5:Y7) -> 0 | Z8: =SUM(Z5:Z7) -> 0 | AA8: =SUM(AA5:AA7) -> 0 | AB8: =SUM(AB5:AB7) -> 0 | ... AG8: =SUM(AG5:AG7) -> 197621.3
C9: 10000 | O9: =O8/C9 -> 384.54049
B10: 市场2025年新店TC统计 | T10: 市场2024年TC统计
B11: 直营门店 | C11: 1月 | D11: 2月 | E11: 3月 | F11: 4月 | G11: 5月 | H11: 6月 | I11: 7月 | J11: 8月 | K11: 9月 | L11: 10月 | M11: 11月 | N11: 12月 | O11: 合计 | P11: 12月日均环比11月 | Q11: 12月日均环比11月日均 | R11: 12月同比 | T11: 直营门店 | U11: 1月 | V11: 2月 | W11: 3月 | X11: 4月 | Y11: 5月 | Z11: 6月 | AA11: 7月 | AB11: 8月 | AC11: 9月 | AD11: 10月 | AE11: 11月 | AF11: 12月 | AG11: 合计
B13: 铁机路店 | D13: 11031 | E13: 16699 | F13: 15057 | G13: 15635 | H13: 14088 | I13: 15390 | J13: 17420 | K13: 15386 | L13: 17644 | M13: 16481 | N13: 19011 | O13: =SUM(C13:N13) -> 173842 | P13: =(N13/31-M13/30)/(M13/30) -> 0.1163001 | Q13: =N13/31-M13/30 -> 63.891398 | AG13: =SUM(U13:AF13) -> 0
B14: 蔡甸中百店 | C14: 9977 | D14: 9532 | E14: 9150 | F14: 8784 | G14: 9600 | H14: 8774 | I14: 9673 | J14: 9959 | K14: 10271 | L14: 11244 | M14: 11090 | N14: 12735 | O14: =SUM(C14:N14) -> 120789 | P14: =(N14/31-M14/30)/(M14/30) -> 0.11128887 | Q14: =N14/31-M14/30 -> 41.139785 | R14: =N14/31-AF14/31 -> 42.290323 | AE14: 11983 | AF14: 11424 | AG14: =SUM(U14:AF14) -> 23407
B15: 东辉花园店 | E15: 4374 | F15: 12463 | G15: 11248 | H15: 11659 | I15: 14095 | J15: 12587 | K15: 10681 | L15: 10796 | M15: 10313 | N15: 12806 | O15: =SUM(C15:N15) -> 111022 | P15: =(N15/31-M15/30)/(M15/30) -> 0.20167781 | Q15: =N15/31-M15/30 -> 69.330108 | AG15: =SUM(U15:AF15) -> 0
B16: 合计 | C16: =SUM(C13:C15) -> 9977 | D16: =SUM(D13:D15) -> 20563 | E16: =SUM(E13:E15) -> 30223 | F16: =SUM(F13:F15) -> 36304 | G16: =SUM(G13:G15) -> 36483 | H16: =SUM(H13:H15) -> 34521 | I16: =SUM(I13:I15) -> 39158 | J16: =SUM(J13:J15) -> 39966 | ... O16: =SUM(O13:O15) -> 405653 | P16: =(N16/31-M16/30)/(M16/30) -> 0.13807514 | Q16: =N16/31-M16/30 -> 174.36129 | T16: 合计 | U16: =SUM(U13:U15) -> 0 | V16: =SUM(V13:V15) -> 0 | W16: =SUM(W13:W15) -> 0 | X16: =SUM(X13:X15) -> 0 | Y16: =SUM(Y13:Y15) -> 0 | Z16: =SUM(Z13:Z15) -> 0 | AA16: =SUM(AA13:AA15) -> 0 | AB16: =SUM(AB13:AB15) -> 0 | ... AG16: =SUM(AG13:AG15) -> 23407
B18: 市场2025年新店AC统计 | T18: 市场2024年AC统计
B19: 直营门店 | C19: 1月 | D19: 2月 | E19: 3月 | F19: 4月 | G19: 5月 | H19: 6月 | I19: 7月 | J19: 8月 | K19: 9月 | L19: 10月 | M19: 11月 | N19: 12月 | O19: 合计 | P19: 12月日均环比11月日均 | T19: 直营门店 | U19: 1月 | V19: 2月 | W19: 3月 | X19: 4月 | Y19: 5月 | Z19: 6月 | AA19: 7月 | AB19: 8月 | AC19: 9月 | AD19: 10月 | AE19: 11月 | AF19: 12月 | AG19: 合计
B21: 铁机路店 | D21: =D5/D13 -> 9.0695585 | E21: =E5/E13 -> 9.3287562 | F21: =F5/F13 -> 9.4399283 | G21: =G5/G13 -> 9.3449933 | H21: =H5/H13 -> 9.4040034 | I21: =I5/I13 -> 9.7140962 | J21: =J5/J13 -> 9.4978995 | K21: =K5/K13 -> 9.0069238 | L21: 9.5504183 | M21: 9.3682246 | N21: 9.523691 | O21: =O5/O13 -> 9.399632 | P21: =N21-M21 -> 0.1554664 | U21: =U5/U13 -> #DIV/0! | V21: =V5/V13 -> #DIV/0! | W21: =W5/W13 -> #DIV/0! | X21: =X5/X13 -> #DIV/0! | Y21: =Y5/Y13 -> #DIV/0! | Z21: =Z5/Z13 -> #DIV/0! | AA21: =AA5/AA13 -> #DIV/0! | AB21: =AB5/AB13 -> #DIV/0! | AC21: =AC5/AC13 -> #DIV/0! | AG21: =AVERAGE(U21:AF21) -> #DIV/0!
B22: 蔡甸中百店 | C22: =C6/C14 -> 8.2096502 | D22: =D6/D14 -> 7.7739813 | E22: =E6/E14 -> 7.8476721 | F22: =F6/F14 -> 7.9523429 | G22: =G6/G14 -> 8.3922302 | H22: =H6/H14 -> 8.5875815 | I22: =I6/I14 -> 8.763546 | J22: =J6/J14 -> 8.7718355 | K22: =K6/K14 -> 8.6444007 | L22: 8.9840831 | M22: 9.1037827 | N22: 9.4580133 | O22: =O6/O14 -> 8.5845781 | P22: =N22-M22 -> 0.35423066 | U22: =U6/U14 -> #DIV/0! | V22: =V6/V14 -> #DIV/0! | W22: =W6/W14 -> #DIV/0! | X22: =X6/X14 -> #DIV/0! | Y22: =Y6/Y14 -> #DIV/0! | Z22: =Z6/Z14 -> #DIV/0! | AA22: =AA6/AA14 -> #DIV/0! | AB22: =AB6/AB14 -> #DIV/0! | AC22: =AC6/AC14 -> #DIV/0! | AE22: 8.7932321 | AF22: 8.0752801 | AG22: =AG6/AG14 -> 8.4428291
B23: 东辉花园店 | E23: =E7/E15 -> 9.5607225 | F23: =F7/F15 -> 10.226992 | G23: =G7/G15 -> 10.264913 | H23: =H7/H15 -> 10.71125 | I23: =I7/I15 -> 10.429992 | J23: =J7/J15 -> 10.786256 | K23: =K7/K15 -> 10.359934 | L23: 11.075203 | M23: 10.956367 | N23: 10.521178 | O23: =O7/O15 -> 10.578367 | P23: =N23-M23 -> -0.43518916 | U23: =U7/U15 -> #DIV/0! | V23: =V7/V15 -> #DIV/0! | W23: =W7/W15 -> #DIV/0! | X23: =X7/X15 -> #DIV/0! | Y23: =Y7/Y15 -> #DIV/0! | Z23: =Z7/Z15 -> #DIV/0! | AA23: =AA7/AA15 -> #DIV/0! | AB23: =AB7/AB15 -> #DIV/0! | AC23: =AC7/AC15 -> #DIV/0! | AG23: =AVERAGE(U23:AF23) -> #DIV/0!
B24: 合计 | C24: =C8/C16 -> 8.2096502 | D24: =D8/D16 -> 8.4689924 | E24: =E8/E16 -> 8.9139298 | F24: =F8/F16 -> 9.3501923 | G24: =G8/G16 -> 9.3779053 | H24: =H8/H16 -> 9.638003 | I24: =I8/I16 -> 9.7369748 | J24: =J8/J16 -> 9.7227323 | ... O24: =O8/O16 -> 9.4795425 | P24: =N24-M24 -> 0.16017241 | T24: 合计 | U24: =U8/U16 -> #DIV/0! | V24: =V8/V16 -> #DIV/0! | W24: =W8/W16 -> #DIV/0! | X24: =X8/X16 -> #DIV/0! | Y24: =Y8/Y16 -> #DIV/0! | Z24: =Z8/Z16 -> #DIV/0! | AA24: =AA8/AA16 -> #DIV/0! | AB24: =AB8/AB16 -> #DIV/0! | AC24: =AC8/AC16 -> #DIV/0! | AG24: =AVERAGE(U24:AF24) -> #DIV/0!

Sheet 2025年分渠道营业额
A1: 序号 | B1: 经营方式 | C1: 选址类型 | D1: 直营门店 | E1: 堂食营业额 | F1: 堂食TC | G1: 堂食AC | H1: 堂食优惠金额 | I1: 外卖营业额 | J1: 外卖TC | K1: 外卖AC | L1: 外卖优惠金额 | M1: 美团外卖营业额 | N1: 美团TC | O1: 美团AC | P1: 美团优惠金额 | Q1: 饿了么营业额 | R1: 饿了么TC | S1: 饿了么AC | T1: 饿了么优惠金额 | U1: 京东外卖营业额 | V1: 京东TC | W1: 京东AC | X1: 京东优惠金额 | Y1: 总计营业额 | Z1: 堂食营业额占比 | AA1: 外卖营业额占比 | AB1: 美团占比 | AC1: 饿了吗占比 | AD1: 京东占比
A4: 1 | B4: 直营 | C4: 商圈 | D4: 步行街店 | E4: 1424190.4 | F4: 152774 | G4: =E4/F4 -> 9.3222043 | H4: 6366.96 | I4: 0 | J4: 0 | K4: 0 | L4: 0 | O4: 0 | S4: 0 | W4: 0 | Y4: =E4 -> 1424190.4 | Z4: =E4/Y4 -> 1 | AA4: =I4/Y4 -> 0 | AB4: =M4/Y4 -> 0 | AC4: =Q4/Y4 -> 0 | AD4: =U4/Y4 -> 0
A5: 2 | B5: 直营 | C5: 社区 | D5: 新常青十一小区店 | E5: 1549428.5 | F5: 148353 | G5: =E5/F5 -> 10.444201 | H5: 6970.25 | I5: =M5+Q5+U5 -> 147529.15 | J5: =N5+R5+V5 -> 10915 | K5: =I5/J5 -> 13.516184 | L5: =P5+T5+X5 -> 153491.77 | M5: 34635.59 | N5: 2458 | O5: =M5/N5 -> 14.090964 | P5: 37762.71 | Q5: 60484.84 | R5: 4871 | S5: =Q5/R5 -> 12.417335 | T5: 72355.6 | U5: 52408.72 | V5: 3586 | W5: =U5/V5 -> 14.614813 | X5: 43373.46 | Y5: =E5+I5 -> 1696957.7 | Z5: =E5/Y5 -> 0.91306256 | AA5: =I5/Y5 -> 0.086937436 | AB5: =M5/Y5 -> 0.020410403 | AC5: =Q5/Y5 -> 0.035643104 | AD5: =U5/Y5 -> 0.030883929
A6: 3 | B6: 直营 | C6: 写字楼 | D6: 新工厂店 | E6: 2010395.8 | F6: 205286 | G6: =E6/F6 -> 9.793146 | H6: 552.04 | I6: =M6+Q6+U6 -> 189599.52 | J6: =N6+R6+V6 -> 14589 | K6: =I6/J6 -> 12.99606 | L6: =P6+T6+X6 -> 199893.15 | M6: 28280.64 | N6: 1970 | O6: =M6/N6 -> 14.355655 | P6: 30737.36 | Q6: 120726.3 | R6: 10070 | S6: =Q6/R6 -> 11.988709 | T6: 139007 | U6: 40592.58 | V6: 2549 | W6: =U6/V6 -> 15.924904 | X6: 30148.79 | Y6: =E6+I6 -> 2199995.3 | Z6: =E6/Y6 -> 0.91381822 | AA6: =I6/Y6 -> 0.086181785 | AB6: =M6/Y6 -> 0.012854864 | AC6: =Q6/Y6 -> 0.054875709 | AD6: =U6/Y6 -> 0.018451212
A7: 4 | B7: 直营 | C7: 社区 | D7: 铁机路店 | E7: 1408835 | F7: 156488 | G7: =E7/F7 -> 9.002831 | H7: 7244.68 | I7: =M7+Q7+U7 -> 225202.73 | J7: =N7+R7+V7 -> 17909 | K7: =I7/J7 -> 12.574836 | L7: =P7+T7+X7 -> 236370.36 | M7: 46263.07 | N7: 3466 | O7: =M7/N7 -> 13.347683 | P7: 49789.53 | Q7: 77475.48 | R7: 7198 | S7: =Q7/R7 -> 10.763473 | T7: 103254.49 | U7: 101464.18 | V7: 7245 | W7: =U7/V7 -> 14.004718 | X7: 83326.34 | Y7: =E7+I7 -> 1634037.8 | Z7: =E7/Y7 -> 0.86218022 | AA7: =I7/Y7 -> 0.13781978 | AB7: =M7/Y7 -> 0.028312118 | AC7: =Q7/Y7 -> 0.047413519 | AD7: =U7/Y7 -> 0.062094147
A8: 6 | B8: 合伙 | C8: 商圈 | D8: 蔡甸中百店 | E8: 959607.05 | F8: 114921 | G8: =E8/F8 -> 8.3501453 | H8: 3406.15 | I8: =M8+Q8+U8 -> 77370.15 | J8: =N8+R8+V8 -> 6270 | K8: =I8/J8 -> 12.339737 | L8: =P8+T8+X8 -> 85922.72 | M8: 15829.53 | N8: 1182 | O8: =M8/N8 -> 13.392157 | P8: 16790.07 | Q8: 32143.37 | R8: 3004 | S8: =Q8/R8 -> 10.70019 | T8: 43181.38 | U8: 29397.25 | V8: 2084 | W8: =U8/V8 -> 14.106166 | X8: 25951.27 | Y8: =E8+I8 -> 1036977.2 | Z8: =E8/Y8 -> 0.92538876 | AA8: =I8/Y8 -> 0.074611235 | AB8: =M8/Y8 -> 0.01526507 | AC8: =Q8/Y8 -> 0.030997181 | AD8: =U8/Y8 -> 0.028348984
A9: 7 | B9: 合伙 | C9: 商圈 | D9: 光谷华科店 | E9: 5298691 | F9: 451828 | G9: =E9/F9 -> 11.72723 | H9: 45071.87 | I9: =M9+Q9+U9 -> 284280.47 | J9: =N9+R9+V9 -> 21671 | K9: =I9/J9 -> 13.118013 | L9: =P9+T9+X9 -> 312306.25 | M9: 71016.45 | N9: 5006 | O9: =M9/N9 -> 14.186266 | P9: 76967.85 | Q9: 143792.59 | R9: 11820 | S9: =Q9/R9 -> 12.165194 | T9: 175775.76 | U9: 69471.43 | V9: 4845 | W9: =U9/V9 -> 14.338788 | X9: 59562.64 | Y9: =E9+I9 -> 5582971.4 | Z9: =E9/Y9 -> 0.94908079 | AA9: =I9/Y9 -> 0.050919206 | AB9: =M9/Y9 -> 0.012720189 | AC9: =Q9/Y9 -> 0.025755566 | AD9: =U9/Y9 -> 0.012443451
A10: 8 | B10: 合伙 | C10: 社区 | D10: 新华路店 | E10: 2346381 | F10: 244713 | G10: =E10/F10 -> 9.5882972 | H10: 14673.73 | I10: =M10+Q10+U10 -> 407120.57 | J10: =N10+R10+V10 -> 29394 | K10: =I10/J10 -> 13.850465 | L10: =P10+T10+X10 -> 422011.77 | M10: 163281.47 | N10: 11085 | O10: =M10/N10 -> 14.729948 | P10: 167755.23 | Q10: 145707.3 | R10: 11746 | S10: =Q10/R10 -> 12.404844 | T10: 175841.29 | U10: 98131.8 | V10: 6563 | W10: =U10/V10 -> 14.952278 | X10: 78415.25 | Y10: =E10+I10 -> 2753501.5 | Z10: =E10/Y10 -> 0.85214442 | AA10: =I10/Y10 -> 0.14785558 | AB10: =M10/Y10 -> 0.059299575 | AC10: =Q10/Y10 -> 0.052917094 | AD10: =U10/Y10 -> 0.035638912
A11: 9 | B11: 合伙 | C11: 社区 | D11: 东辉花园店 | E11: 965479.06 | F11: 94734 | G11: =E11/F11 -> 10.191474 | H11: 22397.24 | I11: =M11+Q11+U11 -> 208952.36 | J11: =N11+R11+V11 -> 16604 | K11: =I11/J11 -> 12.584459 | L11: =P11+T11+X11 -> 214423.78 | M11: 38119.01 | N11: 2728 | O11: =M11/N11 -> 13.973244 | P11: 38824.79 | Q11: 84910.67 | R11: 7891 | S11: =Q11/R11 -> 10.760445 | T11: 108217.01 | U11: 85922.68 | V11: 5985 | W11: =U11/V11 -> 14.356338 | X11: 67381.98 | Y11: =E11+I11 -> 1174431.4 | Z11: =E11/Y11 -> 0.82208211 | AA11: =I11/Y11 -> 0.17791789 | AB11: =M11/Y11 -> 0.032457417 | AC11: =Q11/Y11 -> 0.072299386 | AD11: =U11/Y11 -> 0.073161088
A12: 总计 | E12: =SUM(E4:E11) -> 15963008 | F12: =SUM(F4:F11) -> 1569097 | G12: =E12/F12 -> 10.173372 | H12: =SUM(H4:H11) -> 106682.92 | I12: =SUM(I4:I11) -> 1540054.9 | J12: =SUM(J4:J11) -> 117352 | K12: =I12/J12 -> 13.123381 | L12: =P12+T12+X12 -> 1624419.8 | M12: =SUM(M4:M11) -> 397425.76 | N12: =SUM(N4:N11) -> 27895 | O12: =M12/N12 -> 14.247204 | P12: =SUM(P4:P11) -> 418627.54 | Q12: =SUM(Q4:Q11) -> 665240.55 | R12: =SUM(R4:R11) -> 56600 | S12: =Q12/R12 -> 11.753367 | T12: =SUM(T4:T11) -> 817632.53 | U12: =SUM(U4:U11) -> 477388.64 | V12: =SUM(V4:V11) -> 32857 | W12: =U12/V12 -> 14.529283 | X12: =SUM(X4:X11) -> 388159.73 | Y12: =SUM(Y4:Y11) -> 17503063 | Z12: =E12/Y12 -> 0.91201226 | AA12: =I12/Y12 -> 0.087987741 | AB12: =M12/Y12 -> 0.02270607 | AC12: =Q12/Y12 -> 0.038007094 | AD12: =U12/Y12 -> 0.027274577

Sheet 2025年12月 堂食&外卖销售统计
A1: 序号 | B1: 经营方式 | C1: 选址类型 | D1: 直营门店 | E1: 堂食营业额 | F1: 堂食TC | G1: 堂食AC | H1: 堂食优惠金额 | I1: 外卖营业额 | J1: 外卖TC | K1: 外卖AC | L1: 外卖优惠金额 | M1: 美团外卖营业额 | N1: 美团TC | O1: 美团AC | P1: 美团优惠金额 | Q1: 饿了么营业额 | R1: 饿了么TC | S1: 饿了么AC | T1: 饿了么优惠金额 | U1: 京东外卖营业额 | V1: 京东TC | W1: 京东AC | X1: 京东优惠金额 | Y1: 总计营业额 | Z1: 堂食营业额占比 | AA1: 外卖营业额占比 | AB1: 美团占比 | AC1: 饿了吗占比 | AD1: 京东占比
A4: 1 | B4: 直营 | C4: 商圈 | D4: 步行街店 | E4: 149046.9 | F4: 15976 | G4: =E4/F4 -> 9.3294254 | H4: 1322.7 | I4: 0 | J4: 0 | K4: 0 | L4: 0 | M4: 0 | N4: 0 | O4: 0 | P4: 0 | Q4: 0 | R4: 0 | S4: 0 | T4: 0 | U4: 0 | V4: 0 | W4: 0 | X4: 0 | Y4: =E4 -> 149046.9 | Z4: =E4/Y4 -> 1 | AA4: =I4/Y4 -> 0 | AB4: =M4/Y4 -> 0 | AC4: =Q4/Y4 -> 0 | AD4: =U4/Y4 -> 0
A5: 2 | B5: 直营 | C5: 社区 | D5: 新常青十一小区店 | E5: 128437.52 | F5: 12342 | G5: =E5/F5 -> 10.40654 | H5: 101.58 | I5: =M5+Q5+U5 -> 48986.24 | J5: =N5+R5+V5 -> 3560 | K5: =I5/J5 -> 13.76018 | L5: =P5+T5+X5 -> 46584.06 | M5: 8216.79 | N5: 582 | O5: =M5/N5 -> 14.118196 | P5: 8499.61 | Q5: 11535.19 | R5: 1001 | S5: =Q5/R5 -> 11.523666 | T5: 13224.85 | U5: 29234.26 | V5: 1977 | W5: =U5/V5 -> 14.787183 | X5: 24859.6 | Y5: =E5+I5 -> 177423.76 | Z5: =E5/Y5 -> 0.72390259 | AA5: =I5/Y5 -> 0.27609741 | AB5: =M5/Y5 -> 0.046311666 | AC5: =Q5/Y5 -> 0.065014911 | AD5: =U5/Y5 -> 0.16477083
A6: 3 | B6: 直营 | C6: 写字楼 | D6: 新工厂店 | E6: 169114.78 | F6: 17274 | G6: =E6/F6 -> 9.7901343 | H6: 26.82 | I6: =M6+Q6+U6 -> 79266.87 | J6: =N6+R6+V6 -> 6244 | K6: =I6/J6 -> 12.694886 | L6: =P6+T6+X6 -> 77097.3 | M6: 10763.98 | N6: 716 | O6: =M6/N6 -> 15.033492 | P6: 11069.12 | Q6: 32753.51 | R6: 3280 | S6: =Q6/R6 -> 9.9858262 | T6: 39530.99 | U6: 35749.38 | V6: 2248 | W6: =U6/V6 -> 15.902749 | X6: 26497.19 | Y6: =E6+I6 -> 248381.65 | Z6: =E6/Y6 -> 0.68086664 | AA6: =I6/Y6 -> 0.31913336 | AB6: =M6/Y6 -> 0.043336454 | AC6: =Q6/Y6 -> 0.13186767 | AD6: =U6/Y6 -> 0.14392923
A7: 4 | B7: 直营 | C7: 社区 | D7: 铁机盛世家园店 | E7: 128157.03 | F7: 15121 | G7: =E7/F7 -> 8.4754335 | H7: 33.57 | I7: =M7+Q7+U7 -> 52886.05 | J7: =N7+R7+V7 -> 4445 | K7: =I7/J7 -> 11.897874 | L7: =P7+T7+X7 -> 52149.65 | M7: 6664.46 | N7: 615 | O7: =M7/N7 -> 10.83652 | P7: 6537.94 | Q7: 15197.02 | R7: 1660 | S7: =Q7/R7 -> 9.1548313 | T7: 18232.75 | U7: 31024.57 | V7: 2170 | W7: =U7/V7 -> 14.297037 | X7: 27378.96 | Y7: =E7+I7 -> 181043.08 | Z7: =E7/Y7 -> 0.70788141 | AA7: =I7/Y7 -> 0.29211859 | AB7: =M7/Y7 -> 0.036811459 | AC7: =Q7/Y7 -> 0.083941457 | AD7: =U7/Y7 -> 0.17136568
A8: 6 | B8: 合伙 | C8: 商圈 | D8: 蔡甸中百店 | E8: 85152.35 | F8: 10302 | G8: =E8/F8 -> 8.2656135 | H8: 227.05 | I8: =M8+Q8+U8 -> 35295.45 | J8: =N8+R8+V8 -> 2838 | K8: =I8/J8 -> 12.436734 | L8: =P8+T8+X8 -> 36431.43 | M8: 4036.25 | N8: 302 | O8: =M8/N8 -> 13.365066 | P8: 4366.85 | Q8: 9500.51 | R8: 970 | S8: =Q8/R8 -> 9.7943402 | T8: 12299.34 | U8: 21758.69 | V8: 1566 | W8: =U8/V8 -> 13.894438 | X8: 19765.24 | Y8: =E8+I8 -> 120447.8 | Z8: =E8/Y8 -> 0.70696476 | AA8: =I8/Y8 -> 0.29303524 | AB8: =M8/Y8 -> 0.033510367 | AC8: =Q8/Y8 -> 0.078876576 | AD8: =U8/Y8 -> 0.1806483
A9: 7 | B9: 合伙 | C9: 商圈 | D9: 光谷华科店 | E9: 414033.85 | F9: 35580 | G9: =E9/F9 -> 11.636702 | H9: 3012.4 | I9: =M9+Q9+U9 -> 83649.17 | J9: =N9+R9+V9 -> 6383 | K9: =I9/J9 -> 13.104993 | L9: =P9+T9+X9 -> 81587.01 | M9: 15273.75 | N9: 1012 | O9: =M9/N9 -> 15.092638 | P9: 14783.35 | Q9: 26907.42 | R9: 2450 | S9: =Q9/R9 -> 10.98262 | T9: 29811.85 | U9: 41468 | V9: 2921 | W9: =U9/V9 -> 14.196508 | X9: 36991.81 | Y9: =E9+I9 -> 497683.02 | Z9: =E9/Y9 -> 0.8319228 | AA9: =I9/Y9 -> 0.1680772 | AB9: =M9/Y9 -> 0.030689715 | AC9: =Q9/Y9 -> 0.054065377 | AD9: =U9/Y9 -> 0.083322111
A10: 8 | B10: 合伙 | C10: 社区 | D10: 新华路店 | E10: 175506.46 | F10: 18587 | G10: =E10/F10 -> 9.4424307 | H10: 725.94 | I10: =M10+Q10+U10 -> 69453.01 | J10: =N10+R10+V10 -> 5450 | K10: =I10/J10 -> 12.743672 | L10: =P10+T10+X10 -> 69659.4 | M10: 14978.76 | N10: 1085 | O10: =M10/N10 -> 13.805309 | P10: 16319.94 | Q10: 21379.76 | R10: 2075 | S10: =Q10/R10 -> 10.303499 | T10: 24154.57 | U10: 33094.49 | V10: 2290 | W10: =U10/V10 -> 14.451742 | X10: 29184.89 | Y10: =E10+I10 -> 244959.47 | Z10: =E10/Y10 -> 0.71647142 | AA10: =I10/Y10 -> 0.28352858 | AB10: =M10/Y10 -> 0.061147912 | AC10: =Q10/Y10 -> 0.087278765 | AD10: =U10/Y10 -> 0.1351019
A11: 9 | B11: 合伙 | C11: 社区 | D11: 东辉花园店 | E11: 90632.77 | F11: 8869 | G11: =E11/F11 -> 10.219052 | H11: 127.33 | I11: =M11+Q11+U11 -> 48186.15 | J11: =N11+R11+V11 -> 4253 | K11: =I11/J11 -> 11.32992 | L11: =P11+T11+X11 -> 49401.58 | M11: 4696.59 | N11: 343 | O11: =M11/N11 -> 13.692682 | P11: 5153.71 | Q11: 20084.11 | R11: 2260 | S11: =Q11/R11 -> 8.8867743 | T11: 23415.72 | U11: 23405.45 | V11: 1650 | W11: =U11/V11 -> 14.185121 | X11: 20832.15 | Y11: =E11+I11 -> 138818.92 | Z11: =E11/Y11 -> 0.65288485 | AA11: =I11/Y11 -> 0.34711515 | AB11: =M11/Y11 -> 0.033832492 | AC11: =Q11/Y11 -> 0.14467848 | AD11: =U11/Y11 -> 0.16860418
A12: 总计 | E12: =SUM(E4:E11) -> 1340081.7 | F12: =SUM(F4:F11) -> 134051 | G12: =E12/F12 -> 9.9968046 | H12: =SUM(H4:H11) -> 5577.39 | I12: =SUM(I4:I11) -> 417722.94 | J12: =SUM(J4:J11) -> 33173 | K12: =I12/J12 -> 12.592257 | L12: =P12+T12+X12 -> 412910.43 | M12: =SUM(M4:M11) -> 64630.58 | N12: =SUM(N4:N11) -> 4655 | O12: =M12/N12 -> 13.88412 | P12: =SUM(P4:P11) -> 66730.52 | Q12: =SUM(Q4:Q11) -> 137357.52 | R12: =SUM(R4:R11) -> 13696 | S12: =Q12/R12 -> 10.029025 | T12: =SUM(T4:T11) -> 160670.07 | U12: =SUM(U4:U11) -> 215734.84 | V12: =SUM(V4:V11) -> 14822 | W12: =U12/V12 -> 14.555043 | X12: =SUM(X4:X11) -> 185509.84 | Y12: =SUM(Y4:Y11) -> 1757804.6 | Z12: =E12/Y12 -> 0.76236099 | AA12: =I12/Y12 -> 0.23763901 | AB12: =M12/Y12 -> 0.036767784 | AC12: =Q12/Y12 -> 0.078141518 | AD12: =U12/Y12 -> 0.1227297

Sheet 2025年区域门店销售部类分析
A1: 2025年市场部类营业额统计表
A2: 店型 | B2: 门店名称 | C2: 部类 | D2: 1月 | F2: 2月 | H2: 3月 | J2: 4月 | L2: 5月 | N2: 6月 | P2: 7月 | R2: 8月 | T2: 9月 | V2: 10月 | X2: 11月 | Z2: 12月 | AB2: 合计 | AD2: 12月vs11月日均 | AE2: 12月vs11月日均 | AF2: 年销售量占比 | AG2: 年销售额占比
D3: 销售数量 | E3: 销售额 | F3: 销售数量 | G3: 销售额 | H3: 销售数量 | I3: 销售额 | J3: 销售数量 | K3: 销售额 | L3: 销售数量 | M3: 销售额 | N3: 销售数量 | O3: 销售额 | P3: 销售数量 | Q3: 销售额 | R3: 销售数量 | S3: 销售额 | T3: 销售数量 | U3: 销售额 | V3: 销售数量 | W3: 销售额 | X3: 销售数量 | Y3: 销售额 | Z3: 销售数量 | AA3: 销售额 | AB3: 销售数量 | AC3: 销售额 | AD3: 销售量环比 | AE3: 销售额环比 | AH3: 粉面 | AI3: 小吃 | AJ3: 饮品 | AK3: 米饭
A4: 小型 | B4: 步行街店 | C4: 小吃类 | D4: 7315 | E4: 23573.74 | F4: 7045 | G4: 21686.35 | H4: 8003 | I4: 24957.5 | J4: 7120 | K4: 21652.5 | L4: 7668 | M4: 23757.35 | N4: 7059 | O4: 22296.93 | P4: 8178 | Q4: 26554.86 | R4: 6605 | S4: 20490.61 | T4: 6407 | U4: 19144.39 | V4: 6372 | W4: 19266.75 | X4: 5942 | Y4: 17030.71 | Z4: 7150 | AA4: 20254.86 | AB4: =D4+F4+H4+J4+L4+N4+P4+R4+T4+V4+X4+Z4 -> 84864 | AC4: =E4+G4+I4+K4+M4+O4+Q4+S4+U4+W4+Y4+AA4 -> 260666.55 | AD4: =Z4/31-X4/30 -> 32.578495 | AE4: =AA4/31-Y4/30 -> 85.692247 | AF4: =AB4/SUM($AB$4:$AB$14) -> 0.32394673 | AG4: =AC4/SUM($AC$4:$AC$14) -> 0.18302788 | AI4: =AG4 -> 0.18302788 | AJ4: =AG7 -> 0.072024988 | AK4: =AG10+AG13 -> 0.060244773
C5: 热干系列 | D5: 6720 | E5: 46620.21 | F5: 6970 | G5: 48608.21 | H5: 7308 | I5: 50636 | J5: 6963 | K5: 49050 | L5: 7029 | M5: 50234.87 | N5: 5915 | O5: 42225.75 | P5: 6810 | Q5: 48605.85 | R5: 5525 | S5: 40200.88 | T5: 5327 | U5: 37516.56 | V5: 5079 | W5: 35409.59 | X5: 2640 | Y5: 16944.37 | Z5: 4150 | AA5: 30292.14 | AB5: =D5+F5+H5+J5+L5+N5+P5+R5+T5+V5+X5+Z5 -> 70436 | AC5: =E5+G5+I5+K5+M5+O5+Q5+S5+U5+W5+Y5+AA5 -> 496344.43 | AD5: =Z5/31-X5/30 -> 45.870968 | AE5: =AA5/31-Y5/30 -> 412.35347 | AF5: =AB5/SUM($AB$4:$AB$14) -> 0.26887151 | AG5: =AC5/SUM($AC$4:$AC$14) -> 0.34850987 | AH5: =AG5+AG6+AG11 -> 0.43981798
C6: 汤粉面 | X6: =230+2433 -> 2663 | Y6: =1610+18719.47 -> 20329.47 | Z6: 2579 | AA6: 17513.49 | AB6: =D6+F6+H6+J6+L6+N6+P6+R6+T6+V6+X6+Z6 -> 5242 | AC6: =E6+G6+I6+K6+M6+O6+Q6+S6+U6+W6+Y6+AA6 -> 37842.96 | AD6: =Z6/31-X6/30 -> -5.5731183 | AE6: =AA6/31-Y6/30 -> -112.69771 | AF6: =AB6/SUM($AB$4:$AB$14) -> 0.020010001 | AG6: =AC6/SUM($AC$4:$AC$14) -> 0.026571559
C7: 甜品类 | D7: 3114 | E7: 8967.77 | F7: 2749 | G7: 7933.61 | H7: 3138 | I7: 8944.5 | J7: 3029 | K7: 8693 | L7: 3391 | M7: 9897.7 | N7: 2707 | O7: 7847.27 | P7: 4128 | Q7: 12173.43 | R7: 3247 | S7: 9546.85 | T7: 2369 | U7: 6921.58 | V7: 2224 | W7: 6411.44 | X7: 2372 | Y7: 6886.6 | Z7: 2906 | AA7: 8353.55 | AB7: =D7+F7+H7+J7+L7+N7+P7+R7+T7+V7+X7+Z7 -> 35374 | AC7: =E7+G7+I7+K7+M7+O7+Q7+S7+U7+W7+Y7+AA7 -> 102577.3 | AD7: =Z7/31-X7/30 -> 14.675269 | AE7: =AA7/31-Y7/30 -> 39.916022 | AF7: =AB7/SUM($AB$4:$AB$14) -> 0.13503124 | AG7: =AC7/SUM($AC$4:$AC$14) -> 0.072024988
C8: 套餐系列 | D8: 1826 | E8: 14605.91 | F8: 1917 | G8: 15336 | H8: 2111 | I8: 16888 | J8: 2808 | K8: 23531.9 | L8: 3272 | M8: 27403.11 | N8: 2521 | O8: 20996.18 | P8: 3377 | Q8: 28611.01 | R8: 2858 | S8: 23696.46 | T8: 2457 | U8: 19924.27 | V8: 2544 | W8: 20758.72 | X8: 3081 | Y8: 26127.94 | Z8: 4563 | AA8: 38273.14 | AB8: =D8+F8+H8+J8+L8+N8+P8+R8+T8+V8+X8+Z8 -> 33335 | AC8: =E8+G8+I8+K8+M8+O8+Q8+S8+U8+W8+Y8+AA8 -> 276152.64 | AD8: =Z8/31-X8/30 -> 44.493548 | AE8: =AA8/31-Y8/30 -> 363.68609 | AF8: =AB8/SUM($AB$4:$AB$14) -> 0.12724788 | AG8: =AC8/SUM($AC$4:$AC$14) -> 0.19390148
C9: 养生粥类 | D9: 1216 | E9: 3207 | F9: 1025 | G9: 2707 | H9: 1186 | I9: 3128 | J9: 1165 | K9: 3052 | L9: 1179 | M9: 3071.3 | N9: 1063 | O9: 2747.2 | P9: 1103 | Q9: 2798.5 | R9: 1081 | S9: 2737.56 | T9: 1188 | U9: 2970 | V9: 1092 | W9: 2711.68 | X9: 993 | Y9: 2519 | Z9: 874 | AA9: 2144.33 | AB9: =D9+F9+H9+J9+L9+N9+P9+R9+T9+V9+X9+Z9 -> 13165 | AC9: =E9+G9+I9+K9+M9+O9+Q9+S9+U9+W9+Y9+AA9 -> 33793.57 | AD9: =Z9/31-X9/30 -> -4.9064516 | AE9: =AA9/31-Y9/30 -> -14.794731 | AF9: =AB9/SUM($AB$4:$AB$14) -> 0.050254038 | AG9: =AC9/SUM($AC$4:$AC$14) -> 0.023728266
C10: 炒饭类 | D10: 761 | E10: 8013 | F10: 673 | G10: 7130 | H10: 795 | I10: 8112 | J10: 687 | K10: 7111.79 | L10: 636 | M10: 6458.9 | N10: 521 | O10: 5239.84 | P10: 586 | Q10: 6141.71 | R10: 467 | S10: 4903.93 | T10: 513 | U10: 5115.72 | V10: 646 | W10: 6528.9 | X10: 689 | Y10: 6967.71 | Z10: 1104 | AA10: 11902.7 | AB10: =D10+F10+H10+J10+L10+N10+P10+R10+T10+V10+X10+Z10 -> 8078 | AC10: =E10+G10+I10+K10+M10+O10+Q10+S10+U10+W10+Y10+AA10 -> 83626.2 | AD10: =Z10/31-X10/30 -> 12.646237 | AE10: =AA10/31-Y10/30 -> 151.70106 | AF10: =AB10/SUM($AB$4:$AB$14) -> 0.03083571 | AG10: =AC10/SUM($AC$4:$AC$14) -> 0.058718411
C11: 鲜烫系列 | D11: 750 | E11: 10525.44 | F11: 724 | G11: 10140.43 | H11: 701 | I11: 9877 | J11: 471 | K11: 6547.17 | L11: 515 | M11: 7249.58 | N11: 490 | O11: 6937.36 | P11: 418 | Q11: 5930 | R11: 320 | S11: 4527.45 | T11: 477 | U11: 6623.44 | V11: 523 | W11: 7303.03 | X11: 542 | Y11: 7498.38 | Z11: 648 | AA11: 9037.89 | AB11: =D11+F11+H11+J11+L11+N11+P11+R11+T11+V11+X11+Z11 -> 6579 | AC11: =E11+G11+I11+K11+M11+O11+Q11+S11+U11+W11+Y11+AA11 -> 92197.17 | AD11: =Z11/31-X11/30 -> 2.8365591 | AE11: =AA11/31-Y11/30 -> 41.598839 | AF11: =AB11/SUM($AB$4:$AB$14) -> 0.025113658 | AG11: =AC11/SUM($AC$4:$AC$14) -> 0.064736546
C12: 鲜食类 | D12: 226 | E12: 1064 | F12: 172 | G12: 845 | H12: 60 | I12: 270 | J12: 65 | K12: 270 | L12: 79 | M12: 322.38 | N12: 53 | O12: 215.84 | P12: 17 | Q12: 85 | R12: 136 | S12: 646.65 | T12: 30 | U12: 140 | V12: 71 | W12: 345 | X12: 111 | Y12: 532 | Z12: 55 | AA12: 275.8 | AB12: =D12+F12+H12+J12+L12+N12+P12+R12+T12+V12+X12+Z12 -> 1075 | AC12: =E12+G12+I12+K12+M12+O12+Q12+S12+U12+W12+Y12+AA12 -> 5011.67 | AD12: =Z12/31-X12/30 -> -1.9258065 | AE12: =AA12/31-Y12/30 -> -8.8365591 | AF12: =AB12/SUM($AB$4:$AB$14) -> 0.004103539 | AG12: =AC12/SUM($AC$4:$AC$14) -> 0.0035189606
C13: 浇头类 | D13: 94 | E13: 241.5 | F13: 135 | G13: 211 | H13: 115 | I13: 221.5 | J13: 113 | K13: 240.5 | L13: 97 | M13: 241 | N13: 98 | O13: 165.5 | P13: 82 | Q13: 161.33 | R13: 76 | S13: 150 | T13: 46 | U13: 146.5 | V13: 73 | W13: 133.5 | X13: 59 | Y13: 133.5 | Z13: 71 | AA13: 128 | AB13: =D13+F13+H13+J13+L13+N13+P13+R13+T13+V13+X13+Z13 -> 1059 | AC13: =E13+G13+I13+K13+M13+O13+Q13+S13+U13+W13+Y13+AA13 -> 2173.83 | AD13: =Z13/31-X13/30 -> 0.32365591 | AE13: =AA13/31-Y13/30 -> -0.32096774 | AF13: =AB13/SUM($AB$4:$AB$14) -> 0.004042463 | AG13: =AC13/SUM($AC$4:$AC$14) -> 0.0015263619
C14: 盖浇饭 | P14: 116 | Q14: 1333.53 | R14: 373 | S14: 4160.76 | T14: 421 | U14: 4974.2 | V14: 440 | W14: 5277.53 | X14: 569 | Y14: 7187.1 | Z14: 843 | AA14: 10871 | AB14: =D14+F14+H14+J14+L14+N14+P14+R14+T14+V14+X14+Z14 -> 2762 | AC14: =E14+G14+I14+K14+M14+O14+Q14+S14+U14+W14+Y14+AA14 -> 33804.12 | AD14: =Z14/31-X14/30 -> 8.2268817 | AE14: =AA14/31-Y14/30 -> 111.10742 | AF14: =AB14/SUM($AB$4:$AB$14) -> 0.010543232 | AG14: =AC14/SUM($AC$4:$AC$14) -> 0.023735674
B15: 十一小区店 | C15: 小吃类 | D15: 6697 | E15: 21324.9 | F15: 6384 | G15: 20602.49 | H15: 7860 | I15: 25124.61 | J15: 7372 | K15: 24184.11 | L15: 7409 | M15: 24617.44 | N15: 6990 | O15: 23528.83 | P15: 8219 | Q15: 29287.65 | R15: 10414 | S15: 29601.53 | T15: =9353+69+14 -> 9436 | U15: =25267.92+434.67+46.87 -> 25749.46 | V15: =10135+128+609 -> 10872 | W15: =28541.26+807.76+916.61 -> 30265.63 | X15: 12003 | Y15: 27866.25 | Z15: 13035 | AA15: 25183.08 | AB15: =D15+F15+H15+J15+L15+N15+P15+R15+T15+V15+X15+Z15 -> 106691 | AC15: =E15+G15+I15+K15+M15+O15+Q15+S15+U15+W15+Y15+AA15 -> 307335.98 | AD15: =Z15/31-X15/30 -> 20.383871 | AE15: =AA15/31-Y15/30 -> -116.51758 | AF15: =AB15/SUM($AB$15:$AB$27) -> 0.3154849 | AG15: =AC15/SUM($AC$15:$AC$27) -> 0.18134279 | AI15: =AG15 -> 0.18134279 | AJ15: =AG17 -> 0.10240734 | AK15: =AG23+AG20 -> 0.10789769
C16: 热干系列 | D16: 6460 | E16: 44737.25 | F16: 6880 | G16: 47600.56 | H16: 8463 | I16: 57927.4 | J16: 7446 | K16: 51879.5 | L16: 6269 | M16: 45095.75 | N16: 5126 | O16: 37151.93 | P16: 5703 | Q16: 39376.61 | R16: 5793 | S16: 36273.95 | T16: =4955+3 -> 4958 | U16: =30857.91+26.92 -> 30884.83 | V16: =5084+263+85+41+137 -> 5610 | W16: =32205.69+1072.12+850+263.36+742.1 -> 35133.27 | X16: 6127 | Y16: 37668.11 | Z16: 6350 | AA16: 38695.5 | AB16: =D16+F16+H16+J16+L16+N16+P16+R16+T16+V16+X16+Z16 -> 75185 | AC16: =E16+G16+I16+K16+M16+O16+Q16+S16+U16+W16+Y16+AA16 -> 502424.66 | AD16: =Z16/31-X16/30 -> 0.60537634 | AE16: =AA16/31-Y16/30 -> -7.3617312 | AF16: =AB16/SUM($AB$15:$AB$27) -> 0.22232177 | AG16: =AC16/SUM($AC$15:$AC$27) -> 0.29645436 | AH16: =AG16+AG18+AG22 -> 0.45771055
C17: 饮品 | D17: 5385 | E17: 14525.77 | F17: 5288 | G17: 14264.3 | H17: 6469 | I17: 17510.04 | J17: 5872 | K17: 16320.19 | L17: 4954 | M17: 13880.86 | N17: 4204 | O17: 11732.77 | P17: 5375 | Q17: 15259.38 | R17: 5533 | S17: 15080.55 | T17: =4452+1 -> 4453 | U17: =12086.42+2.79 -> 12089.21 | V17: =4851+110 -> 4961 | W17: =13033.74+247.2 -> 13280.94 | X17: 5586 | Y17: 14314.77 | Z17: 5976 | AA17: 15299.05 | AB17: =D17+F17+H17+J17+L17+N17+P17+R17+T17+V17+X17+Z17 -> 64056 | AC17: =E17+G17+I17+K17+M17+O17+Q17+S17+U17+W17+Y17+AA17 -> 173557.83 | AD17: =Z17/31-X17/30 -> 6.5741935 | AE17: =AA17/31-Y17/30 -> 16.358742 | AF17: =AB17/SUM($AB$15:$AB$27) -> 0.18941336 | AG17: =AC17/SUM($AC$15:$AC$27) -> 0.10240734
